Workbook

Sheet Setup
A1: Setup Sesi Cupping
A2: Isi sel kuning. Kode sampel dipakai otomatis di semua sheet.
A4: Sampel | B4: Kode (3 digit) | C4: Nama / keterangan kopi
A5: Sampel 1 | B5: 527 | C5: Ethiopia natural (light roast) | D5: ← contoh kode; ganti sesuai label cup
A6: Sampel 2 | B6: 381 | C6: Robusta Temanggung (dark roast)
A8: Nama sesi / kelas | B8: CONTOH DATA SIMULASI
A10: ID Panelis | B10: Nama Mahasiswa
A11: P01 | B11: Ayu
A12: P02 | B12: Bima
A13: P03 | B13: Citra
A14: P04 | B14: Dewi
A15: P05 | B15: Eka
A16: P06 | B16: Fajar
A17: P07 | B17: Gita
A18: P08 | B18: Hana
A19: P09 | B19: Indra
A20: P10 | B20: Joko
... A40: P30 | B40: Intan

Sheet Afektif
A1: Affective Assessment (SCA-104)
A2: Skor impresi kualitas 1–9. Cup non-uniform & defective: jumlah cup (0–5), kosong = 0.
A3: ID Panelis | B3: Nama | C3: Urutan | D3: Kode Sampel | E3: Skor hedonik (1–9) | M3: Cup (0–5) | O3: Skor CVA | P3: Status
E4: Fragrance | F4: Aroma | G4: Flavor | H4: Aftertaste | I4: Acidity | J4: Sweetness | K4: Mouthfeel | L4: Overall | M4: Non-uniform | N4: Defective
A5: P01 | B5: =IF(Setup!$B$11="","",Setup!$B$11) -> Ayu | C5: 1 | D5: =Setup!$B$5 -> 527 | E5: 6 | F5: 7 | G5: 6 | H5: 8 | I5: 8 | J5: 7 | K5: 8 | L5: 9 | M5: 0 | N5: 0 | O5: =IF(COUNT(E5:L5)=8,0.65625*SUM(E5:L5)+52.75-2*N(M5)-4*N(N5),"") -> 91.46875 | P5: =IF(COUNT(E5:N5)=0,"kosong",IF(COUNT(E5:L5)<8,"belum lengkap","OK")) -> OK
A6: P01 | B6: =IF(Setup!$B$11="","",Setup!$B$11) -> Ayu | C6: 2 | D6: =Setup!$B$6 -> 381 | E6: 7 | F6: 6 | G6: 6 | H6: 7 | I6: 6 | J6: 6 | K6: 6 | L6: 4 | M6: 0 | N6: 0 | O6: =IF(COUNT(E6:L6)=8,0.65625*SUM(E6:L6)+52.75-2*N(M6)-4*N(N6),"") -> 84.25 | P6: =IF(COUNT(E6:N6)=0,"kosong",IF(COUNT(E6:L6)<8,"belum lengkap","OK")) -> OK
A7: P02 | B7: =IF(Setup!$B$12="","",Setup!$B$12) -> Bima | C7: 1 | D7: =Setup!$B$5 -> 527 | E7: 8 | F7: 8 | G7: 7 | H7: 7 | I7: 9 | J7: 8 | K7: 7 | L7: 9 | M7: 1 | N7: 0 | O7: =IF(COUNT(E7:L7)=8,0.65625*SUM(E7:L7)+52.75-2*N(M7)-4*N(N7),"") -> 92.09375 | P7: =IF(COUNT(E7:N7)=0,"kosong",IF(COUNT(E7:L7)<8,"belum lengkap","OK")) -> OK
A8: P02 | B8: =IF(Setup!$B$12="","",Setup!$B$12) -> Bima | C8: 2 | D8: =Setup!$B$6 -> 381 | E8: 6 | F8: 6 | G8: 6 | H8: 6 | I8: 5 | J8: 6 | K8: 6 | L8: 6 | M8: 0 | N8: 0 | O8: =IF(COUNT(E8:L8)=8,0.65625*SUM(E8:L8)+52.75-2*N(M8)-4*N(N8),"") -> 83.59375 | P8: =IF(COUNT(E8:N8)=0,"kosong",IF(COUNT(E8:L8)<8,"belum lengkap","OK")) -> OK
A9: P03 | B9: =IF(Setup!$B$13="","",Setup!$B$13) -> Citra | C9: 1 | D9: =Setup!$B$5 -> 527 | E9: 7 | F9: 8 | G9: 7 | H9: 7 | I9: 9 | J9: 7 | K9: 5 | L9: 7 | M9: 0 | N9: 0 | O9: =IF(COUNT(E9:L9)=8,0.65625*SUM(E9:L9)+52.75-2*N(M9)-4*N(N9),"") -> 90.15625 | P9: =IF(COUNT(E9:N9)=0,"kosong",IF(COUNT(E9:L9)<8,"belum lengkap","OK")) -> OK
A10: P03 | B10: =IF(Setup!$B$13="","",Setup!$B$13) -> Citra | C10: 2 | D10: =Setup!$B$6 -> 381 | E10: 5 | F10: 6 | G10: 4 | H10: 4 | I10: 5 | J10: 7 | K10: 5 | L10: 5 | M10: 0 | N10: 0 | O10: =IF(COUNT(E10:L10)=8,0.65625*SUM(E10:L10)+52.75-2*N(M10)-4*N(N10),"") -> 79.65625 | P10: =IF(COUNT(E10:N10)=0,"kosong",IF(COUNT(E10:L10)<8,"belum lengkap","OK")) -> OK
A11: P04 | B11: =IF(Setup!$B$14="","",Setup!$B$14) -> Dewi | C11: 1 | D11: =Setup!$B$5 -> 527 | E11: 7 | F11: 7 | G11: 8 | H11: 7 | I11: 7 | J11: 8 | K11: 8 | L11: 8 | M11: 0 | N11: 0 | O11: =IF(COUNT(E11:L11)=8,0.65625*SUM(E11:L11)+52.75-2*N(M11)-4*N(N11),"") -> 92.125 | P11: =IF(COUNT(E11:N11)=0,"kosong",IF(COUNT(E11:L11)<8,"belum lengkap","OK")) -> OK
A12: P04 | B12: =IF(Setup!$B$14="","",Setup!$B$14) -> Dewi | C12: 2 | D12: =Setup!$B$6 -> 381 | E12: 5 | F12: 6 | G12: 6 | H12: 6 | I12: 6 | J12: 5 | K12: 5 | L12: 5 | M12: 0 | N12: 0 | O12: =IF(COUNT(E12:L12)=8,0.65625*SUM(E12:L12)+52.75-2*N(M12)-4*N(N12),"") -> 81.625 | P12: =IF(COUNT(E12:N12)=0,"kosong",IF(COUNT(E12:L12)<8,"belum lengkap","OK")) -> OK
A13: P05 | B13: =IF(Setup!$B$15="","",Setup!$B$15) -> Eka | C13: 1 | D13: =Setup!$B$5 -> 527 | E13: 7 | F13: 8 | G13: 7 | H13: 7 | I13: 7 | J13: 8 | K13: 9 | L13: 7 | M13: 0 | N13: 0 | O13: =IF(COUNT(E13:L13)=8,0.65625*SUM(E13:L13)+52.75-2*N(M13)-4*N(N13),"") -> 92.125 | P13: =IF(COUNT(E13:N13)=0,"kosong",IF(COUNT(E13:L13)<8,"belum lengkap","OK")) -> OK
A14: P05 | B14: =IF(Setup!$B$15="","",Setup!$B$15) -> Eka | C14: 2 | D14: =Setup!$B$6 -> 381 | E14: 6 | F14: 4 | G14: 5 | H14: 7 | I14: 4 | J14: 6 | K14: 4 | L14: 7 | M14: 0 | N14: 0 | O14: =IF(COUNT(E14:L14)=8,0.65625*SUM(E14:L14)+52.75-2*N(M14)-4*N(N14),"") -> 80.96875 | P14: =IF(COUNT(E14:N14)=0,"kosong",IF(COUNT(E14:L14)<8,"belum lengkap","OK")) -> OK
A15: P06 | B15: =IF(Setup!$B$16="","",Setup!$B$16) -> Fajar | C15: 1 | D15: =Setup!$B$5 -> 527 | E15: 7 | F15: 7 | G15: 8 | H15: 7 | I15: 7 | J15: 7 | K15: 5 | L15: 9 | M15: 0 | N15: 0 | O15: =IF(COUNT(E15:L15)=8,0.65625*SUM(E15:L15)+52.75-2*N(M15)-4*N(N15),"") -> 90.15625 | P15: =IF(COUNT(E15:N15)=0,"kosong",IF(COUNT(E15:L15)<8,"belum lengkap","OK")) -> OK
A16: P06 | B16: =IF(Setup!$B$16="","",Setup!$B$16) -> Fajar | C16: 2 | D16: =Setup!$B$6 -> 381 | E16: 6 | F16: 7 | G16: 5 | H16: 7 | I16: 6 | J16: 6 | K16: 5 | L16: 7 | M16: 0 | N16: 0 | O16: =IF(COUNT(E16:L16)=8,0.65625*SUM(E16:L16)+52.75-2*N(M16)-4*N(N16),"") -> 84.90625 | P16: =IF(COUNT(E16:N16)=0,"kosong",IF(COUNT(E16:L16)<8,"belum lengkap","OK")) -> OK
A17: P07 | B17: =IF(Setup!$B$17="","",Setup!$B$17) -> Gita | C17: 1 | D17: =Setup!$B$5 -> 527 | E17: 8 | F17: 8 | G17: 7 | H17: 8 | I17: 7 | J17: 5 | K17: 7 | L17: 9 | M17: 0 | N17: 0 | O17: =IF(COUNT(E17:L17)=8,0.65625*SUM(E17:L17)+52.75-2*N(M17)-4*N(N17),"") -> 91.46875 | P17: =IF(COUNT(E17:N17)=0,"kosong",IF(COUNT(E17:L17)<8,"belum lengkap","OK")) -> OK
A18: P07 | B18: =IF(Setup!$B$17="","",Setup!$B$17) -> Gita | C18: 2 | D18: =Setup!$B$6 -> 381 | E18: 6 | F18: 5 | G18: 6 | H18: 7 | I18: 3 | J18: 6 | K18: 6 | L18: 6 | M18: 1 | N18: 0 | O18: =IF(COUNT(E18:L18)=8,0.65625*SUM(E18:L18)+52.75-2*N(M18)-4*N(N18),"") -> 80.28125 | P18: =IF(COUNT(E18:N18)=0,"kosong",IF(COUNT(E18:L18)<8,"belum lengkap","OK")) -> OK
A19: P08 | B19: =IF(Setup!$B$18="","",Setup!$B$18) -> Hana | C19: 1 | D19: =Setup!$B$5 -> 527 | E19: 8 | F19: 7 | G19: 6 | H19: 8 | I19: 8 | J19: 8 | K19: 8 | L19: 7 | M19: 0 | N19: 0 | O19: =IF(COUNT(E19:L19)=8,0.65625*SUM(E19:L19)+52.75-2*N(M19)-4*N(N19),"") -> 92.125 | P19: =IF(COUNT(E19:N19)=0,"kosong",IF(COUNT(E19:L19)<8,"belum lengkap","OK")) -> OK
A20: P08 | B20: =IF(Setup!$B$18="","",Setup!$B$18) -> Hana | C20: 2 | D20: =Setup!$B$6 -> 381 | E20: 2 | F20: 5 | G20: 5 | H20: 6 | I20: 6 | J20: 5 | K20: 4 | L20: 5 | M20: 0 | N20: 0 | O20: =IF(COUNT(E20:L20)=8,0.65625*SUM(E20:L20)+52.75-2*N(M20)-4*N(N20),"") -> 77.6875 | P20: =IF(COUNT(E20:N20)=0,"kosong",IF(COUNT(E20:L20)<8,"belum lengkap","OK")) -> OK
A21: P09 | B21: =IF(Setup!$B$19="","",Setup!$B$19) -> Indra | C21: 1 | D21: =Setup!$B$5 -> 527 | E21: 7 | F21: 9 | G21: 7 | H21: 7 | I21: 7 | J21: 6 | K21: 7 | L21: 7 | M21: 0 | N21: 0 | O21: =IF(COUNT(E21:L21)=8,0.65625*SUM(E21:L21)+52.75-2*N(M21)-4*N(N21),"") -> 90.15625 | P21: =IF(COUNT(E21:N21)=0,"kosong",IF(COUNT(E21:L21)<8,"belum lengkap","OK")) -> OK
A22: P09 | B22: =IF(Setup!$B$19="","",Setup!$B$19) -> Indra | C22: 2 | D22: =Setup!$B$6 -> 381 | E22: 5 | F22: 6 | G22: 5 | H22: 6 | I22: 6 | J22: 6 | K22: 5 | L22: 4 | M22: 0 | N22: 0 | O22: =IF(COUNT(E22:L22)=8,0.65625*SUM(E22:L22)+52.75-2*N(M22)-4*N(N22),"") -> 80.96875 | P22: =IF(COUNT(E22:N22)=0,"kosong",IF(COUNT(E22:L22)<8,"belum lengkap","OK")) -> OK
A23: P10 | B23: =IF(Setup!$B$20="","",Setup!$B$20) -> Joko | C23: 1 | D23: =Setup!$B$5 -> 527 | E23: 8 | F23: 8 | G23: 9 | H23: 6 | I23: 8 | J23: 9 | K23: 7 | L23: 8 | M23: 0 | N23: 0 | O23: =IF(COUNT(E23:L23)=8,0.65625*SUM(E23:L23)+52.75-2*N(M23)-4*N(N23),"") -> 94.09375 | P23: =IF(COUNT(E23:N23)=0,"kosong",IF(COUNT(E23:L23)<8,"belum lengkap","OK")) -> OK
A24: P10 | B24: =IF(Setup!$B$20="","",Setup!$B$20) -> Joko | C24: 2 | D24: =Setup!$B$6 -> 381 | E24: 6 | F24: 5 | G24: 4 | H24: 5 | I24: 6 | J24: 7 | K24: 6 | L24: 6 | M24: 0 | N24: 0 | O24: =IF(COUNT(E24:L24)=8,0.65625*SUM(E24:L24)+52.75-2*N(M24)-4*N(N24),"") -> 82.28125 | P24: =IF(COUNT(E24:N24)=0,"kosong",IF(COUNT(E24:L24)<8,"belum lengkap","OK")) -> OK
A25: P11 | B25: =IF(Setup!$B$21="","",Setup!$B$21) -> Kirana | C25: 1 | D25: =Setup!$B$5 -> 527 | E25: 8 | F25: 6 | G25: 7 | H25: 8 | I25: 7 | J25: 8 | K25: 7 | L25: 7 | M25: 0 | N25: 0 | O25: =IF(COUNT(E25:L25)=8,0.65625*SUM(E25:L25)+52.75-2*N(M25)-4*N(N25),"") -> 90.8125 | P25: =IF(COUNT(E25:N25)=0,"kosong",IF(COUNT(E25:L25)<8,"belum lengkap","OK")) -> OK
A26: P11 | B26: =IF(Setup!$B$21="","",Setup!$B$21) -> Kirana | C26: 2 | D26: =Setup!$B$6 -> 381 | E26: 5 | F26: 7 | G26: 5 | H26: 6 | I26: 8 | J26: 4 | K26: 6 | L26: 5 | M26: 0 | N26: 0 | O26: =IF(COUNT(E26:L26)=8,0.65625*SUM(E26:L26)+52.75-2*N(M26)-4*N(N26),"") -> 82.9375 | P26: =IF(COUNT(E26:N26)=0,"kosong",IF(COUNT(E26:L26)<8,"belum lengkap","OK")) -> OK
A27: P12 | B27: =IF(Setup!$B$22="","",Setup!$B$22) -> Lutfi | C27: 1 | D27: =Setup!$B$5 -> 527 | E27: 7 | F27: 9 | G27: 8 | H27: 9 | I27: 7 | J27: 8 | K27: 7 | L27: 8 | M27: 0 | N27: 0 | O27: =IF(COUNT(E27:L27)=8,0.65625*SUM(E27:L27)+52.75-2*N(M27)-4*N(N27),"") -> 94.09375 | P27: =IF(COUNT(E27:N27)=0,"kosong",IF(COUNT(E27:L27)<8,"belum lengkap","OK")) -> OK
A28: P12 | B28: =IF(Setup!$B$22="","",Setup!$B$22) -> Lutfi | C28: 2 | D28: =Setup!$B$6 -> 381 | E28: 7 | F28: 5 | G28: 6 | H28: 5 | I28: 5 | J28: 7 | K28: 5 | L28: 6 | M28: 0 | N28: 0 | O28: =IF(COUNT(E28:L28)=8,0.65625*SUM(E28:L28)+52.75-2*N(M28)-4*N(N28),"") -> 82.9375 | P28: =IF(COUNT(E28:N28)=0,"kosong",IF(COUNT(E28:L28)<8,"belum lengkap","OK")) -> OK
A29: P13 | B29: =IF(Setup!$B$23="","",Setup!$B$23) -> Maya | C29: 1 | D29: =Setup!$B$5 -> 527 | E29: 7 | F29: 8 | G29: 7 | H29: 5 | I29: 7 | J29: 6 | K29: 8 | L29: 7 | M29: 0 | N29: 0 | O29: =IF(COUNT(E29:L29)=8,0.65625*SUM(E29:L29)+52.75-2*N(M29)-4*N(N29),"") -> 88.84375 | P29: =IF(COUNT(E29:N29)=0,"kosong",IF(COUNT(E29:L29)<8,"belum lengkap","OK")) -> OK
A30: P13 | B30: =IF(Setup!$B$23="","",Setup!$B$23) -> Maya | C30: 2 | D30: =Setup!$B$6 -> 381 | E30: 4 | F30: 8 | G30: 4 | H30: 6 | I30: 6 | J30: 6 | K30: 6 | L30: 7 | M30: 0 | N30: 0 | O30: =IF(COUNT(E30:L30)=8,0.65625*SUM(E30:L30)+52.75-2*N(M30)-4*N(N30),"") -> 83.59375 | P30: =IF(COUNT(E30:N30)=0,"kosong",IF(COUNT(E30:L30)<8,"belum lengkap","OK")) -> OK
A31: P14 | B31: =IF(Setup!$B$24="","",Setup!$B$24) -> Nanda | C31: 1 | D31: =Setup!$B$5 -> 527 | E31: 7 | F31: 5 | G31: 8 | H31: 7 | I31: 8 | J31: 7 | K31: 9 | L31: 8 | M31: 0 | N31: 0 | O31: =IF(COUNT(E31:L31)=8,0.65625*SUM(E31:L31)+52.75-2*N(M31)-4*N(N31),"") -> 91.46875 | P31: =IF(COUNT(E31:N31)=0,"kosong",IF(COUNT(E31:L31)<8,"belum lengkap","OK")) -> OK
A32: P14 | B32: =IF(Setup!$B$24="","",Setup!$B$24) -> Nanda | C32: 2 | D32: =Setup!$B$6 -> 381 | E32: 7 | F32: 6 | G32: 4 | H32: 6 | I32: 6 | J32: 7 | K32: 5 | L32: 7 | M32: 0 | N32: 0 | O32: =IF(COUNT(E32:L32)=8,0.65625*SUM(E32:L32)+52.75-2*N(M32)-4*N(N32),"") -> 84.25 | P32: =IF(COUNT(E32:N32)=0,"kosong",IF(COUNT(E32:L32)<8,"belum lengkap","OK")) -> OK
A33: P15 | B33: =IF(Setup!$B$25="","",Setup!$B$25) -> Oki | C33: 1 | D33: =Setup!$B$5 -> 527 | E33: 8 | F33: 6 | G33: 8 | H33: 6 | I33: 7 | J33: 6 | K33: 7 | L33: 9 | M33: 0 | N33: 0 | O33: =IF(COUNT(E33:L33)=8,0.65625*SUM(E33:L33)+52.75-2*N(M33)-4*N(N33),"") -> 90.15625 | P33: =IF(COUNT(E33:N33)=0,"kosong",IF(COUNT(E33:L33)<8,"belum lengkap","OK")) -> OK
A34: P15 | B34: =IF(Setup!$B$25="","",Setup!$B$25) -> Oki | C34: 2 | D34: =Setup!$B$6 -> 381 | E34: 6 | F34: 8 | G34: 8 | H34: 5 | I34: 6 | J34: 5 | K34: 7 | L34: 7 | M34: 0 | N34: 0 | O34: =IF(COUNT(E34:L34)=8,0.65625*SUM(E34:L34)+52.75-2*N(M34)-4*N(N34),"") -> 86.875 | P34: =IF(COUNT(E34:N34)=0,"kosong",IF(COUNT(E34:L34)<8,"belum lengkap","OK")) -> OK
A35: P16 | B35: =IF(Setup!$B$26="","",Setup!$B$26) -> Putri | C35: 1 | D35: =Setup!$B$5 -> 527 | E35: 7 | F35: 8 | G35: 8 | H35: 8 | I35: 8 | J35: 6 | K35: 7 | L35: 7 | M35: 0 | N35: 0 | O35: =IF(COUNT(E35:L35)=8,0.65625*SUM(E35:L35)+52.75-2*N(M35)-4*N(N35),"") -> 91.46875 | P35: =IF(COUNT(E35:N35)=0,"kosong",IF(COUNT(E35:L35)<8,"belum lengkap","OK")) -> OK
A36: P16 | B36: =IF(Setup!$B$26="","",Setup!$B$26) -> Putri | C36: 2 | D36: =Setup!$B$6 -> 381 | E36: 7 | F36: 6 | G36: 5 | H36: 6 | I36: 5 | J36: 7 | K36: 4 | L36: 6 | M36: 0 | N36: 0 | O36: =IF(COUNT(E36:L36)=8,0.65625*SUM(E36:L36)+52.75-2*N(M36)-4*N(N36),"") -> 82.9375 | P36: =IF(COUNT(E36:N36)=0,"kosong",IF(COUNT(E36:L36)<8,"belum lengkap","OK")) -> OK
A37: P17 | B37: =IF(Setup!$B$27="","",Setup!$B$27) -> Raka | C37: 1 | D37: =Setup!$B$5 -> 527 | E37: 6 | F37: 6 | G37: 7 | H37: 8 | I37: 7 | J37: 9 | K37: 6 | L37: 6 | M37: 0 | N37: 0 | O37: =IF(COUNT(E37:L37)=8,0.65625*SUM(E37:L37)+52.75-2*N(M37)-4*N(N37),"") -> 88.84375 | P37: =IF(COUNT(E37:N37)=0,"kosong",IF(COUNT(E37:L37)<8,"belum lengkap","OK")) -> OK
A38: P17 | B38: =IF(Setup!$B$27="","",Setup!$B$27) -> Raka | C38: 2 | D38: =Setup!$B$6 -> 381 | E38: 8 | F38: 4 | G38: 5 | H38: 4 | I38: 6 | J38: 6 | K38: 4 | L38: 4 | M38: 0 | N38: 0 | O38: =IF(COUNT(E38:L38)=8,0.65625*SUM(E38:L38)+52.75-2*N(M38)-4*N(N38),"") -> 79.65625 | P38: =IF(COUNT(E38:N38)=0,"kosong",IF(COUNT(E38:L38)<8,"belum lengkap","OK")) -> OK
A39: P18 | B39: =IF(Setup!$B$28="","",Setup!$B$28) -> Sari | C39: 1 | D39: =Setup!$B$5 -> 527 | E39: 6 | F39: 6 | G39: 8 | H39: 7 | I39: 8 | J39: 9 | K39: 9 | L39: 7 | M39: 0 | N39: 0 | O39: =IF(COUNT(E39:L39)=8,0.65625*SUM(E39:L39)+52.75-2*N(M39)-4*N(N39),"") -> 92.125 | P39: =IF(COUNT(E39:N39)=0,"kosong",IF(COUNT(E39:L39)<8,"belum lengkap","OK")) -> OK
A40: P18 | B40: =IF(Setup!$B$28="","",Setup!$B$28) -> Sari | C40: 2 | D40: =Setup!$B$6 -> 381 | E40: 6 | F40: 5 | G40: 6 | H40: 6 | I40: 7 | J40: 5 | K40: 5 | L40: 5 | M40: 0 | N40: 0 | O40: =IF(COUNT(E40:L40)=8,0.65625*SUM(E40:L40)+52.75-2*N(M40)-4*N(N40),"") -> 82.28125 | P40: =IF(COUNT(E40:N40)=0,"kosong",IF(COUNT(E40:L40)<8,"belum lengkap","OK")) -> OK
...

Sheet Deskriptif
A1: Descriptive Assessment — Intensitas (SCA-103)
A2: Intensitas 0–15 (0 = tidak terasa, 15 = sangat kuat). Pilihan CATA diisi di sheet 'CATA'.
A3: ID Panelis | B3: Nama | C3: Urutan | D3: Kode Sampel | E3: Intensitas (0–15) | L3: Status
E4: Fragrance | F4: Aroma | G4: Flavor | H4: Aftertaste | I4: Acidity | J4: Sweetness | K4: Mouthfeel
A5: P01 | B5: =IF(Setup!$B$11="","",Setup!$B$11) -> Ayu | C5: 1 | D5: =Setup!$B$5 -> 527 | E5: 7 | F5: 10 | G5: 7 | H5: 7 | I5: 11 | J5: 4 | K5: 7 | L5: =IF(COUNT(E5:K5)=0,"kosong",IF(COUNT(E5:K5)<7,"belum lengkap","OK")) -> OK
A6: P01 | B6: =IF(Setup!$B$11="","",Setup!$B$11) -> Ayu | C6: 2 | D6: =Setup!$B$6 -> 381 | E6: 13 | F6: 7 | G6: 10 | H6: 11 | I6: 2 | J6: 6 | K6: 8 | L6: =IF(COUNT(E6:K6)=0,"kosong",IF(COUNT(E6:K6)<7,"belum lengkap","OK")) -> OK
A7: P02 | B7: =IF(Setup!$B$12="","",Setup!$B$12) -> Bima | C7: 1 | D7: =Setup!$B$5 -> 527 | E7: 6 | F7: 7 | G7: 10 | H7: 7 | I7: 11 | J7: 8 | K7: 10 | L7: =IF(COUNT(E7:K7)=0,"kosong",IF(COUNT(E7:K7)<7,"belum lengkap","OK")) -> OK
A8: P02 | B8: =IF(Setup!$B$12="","",Setup!$B$12) -> Bima | C8: 2 | D8: =Setup!$B$6 -> 381 | E8: 10 | F8: 9 | G8: 11 | H8: 6 | I8: 5 | J8: 6 | K8: 8 | L8: =IF(COUNT(E8:K8)=0,"kosong",IF(COUNT(E8:K8)<7,"belum lengkap","OK")) -> OK
A9: P03 | B9: =IF(Setup!$B$13="","",Setup!$B$13) -> Citra | C9: 1 | D9: =Setup!$B$5 -> 527 | E9: 11 | F9: 5 | G9: 9 | H9: 8 | I9: 10 | J9: 8 | K9: 6 | L9: =IF(COUNT(E9:K9)=0,"kosong",IF(COUNT(E9:K9)<7,"belum lengkap","OK")) -> OK
A10: P03 | B10: =IF(Setup!$B$13="","",Setup!$B$13) -> Citra | C10: 2 | D10: =Setup!$B$6 -> 381 | E10: 8 | F10: 8 | G10: 7 | H10: 6 | I10: 4 | J10: 8 | K10: 8 | L10: =IF(COUNT(E10:K10)=0,"kosong",IF(COUNT(E10:K10)<7,"belum lengkap","OK")) -> OK
A11: P04 | B11: =IF(Setup!$B$14="","",Setup!$B$14) -> Dewi | C11: 1 | D11: =Setup!$B$5 -> 527 | E11: 8 | F11: 7 | G11: 12 | H11: 6 | I11: 12 | J11: 8 | K11: 9 | L11: =IF(COUNT(E11:K11)=0,"kosong",IF(COUNT(E11:K11)<7,"belum lengkap","OK")) -> OK
A12: P04 | B12: =IF(Setup!$B$14="","",Setup!$B$14) -> Dewi | C12: 2 | D12: =Setup!$B$6 -> 381 | E12: 9 | F12: 11 | G12: 8 | H12: 8 | I12: 8 | J12: 5 | K12: 10 | L12: =IF(COUNT(E12:K12)=0,"kosong",IF(COUNT(E12:K12)<7,"belum lengkap","OK")) -> OK
A13: P05 | B13: =IF(Setup!$B$15="","",Setup!$B$15) -> Eka | C13: 1 | D13: =Setup!$B$5 -> 527 | E13: 8 | F13: 13 | G13: 8 | H13: 9 | I13: 12 | J13: 7 | K13: 5 | L13: =IF(COUNT(E13:K13)=0,"kosong",IF(COUNT(E13:K13)<7,"belum lengkap","OK")) -> OK
A14: P05 | B14: =IF(Setup!$B$15="","",Setup!$B$15) -> Eka | C14: 2 | D14: =Setup!$B$6 -> 381 | E14: 8 | F14: 9 | G14: 9 | H14: 9 | I14: 5 | J14: 8 | K14: 11 | L14: =IF(COUNT(E14:K14)=0,"kosong",IF(COUNT(E14:K14)<7,"belum lengkap","OK")) -> OK
A15: P06 | B15: =IF(Setup!$B$16="","",Setup!$B$16) -> Fajar | C15: 1 | D15: =Setup!$B$5 -> 527 | E15: 11 | F15: 9 | G15: 8 | H15: 6 | I15: 11 | J15: 10 | K15: 7 | L15: =IF(COUNT(E15:K15)=0,"kosong",IF(COUNT(E15:K15)<7,"belum lengkap","OK")) -> OK
A16: P06 | B16: =IF(Setup!$B$16="","",Setup!$B$16) -> Fajar | C16: 2 | D16: =Setup!$B$6 -> 381 | E16: 9 | F16: 8 | G16: 7 | H16: 8 | I16: 3 | J16: 5 | K16: 10 | L16: =IF(COUNT(E16:K16)=0,"kosong",IF(COUNT(E16:K16)<7,"belum lengkap","OK")) -> OK
A17: P07 | B17: =IF(Setup!$B$17="","",Setup!$B$17) -> Gita | C17: 1 | D17: =Setup!$B$5 -> 527 | E17: 6 | F17: 7 | G17: 10 | H17: 8 | I17: 11 | J17: 11 | K17: 6 | L17: =IF(COUNT(E17:K17)=0,"kosong",IF(COUNT(E17:K17)<7,"belum lengkap","OK")) -> OK
A18: P07 | B18: =IF(Setup!$B$17="","",Setup!$B$17) -> Gita | C18: 2 | D18: =Setup!$B$6 -> 381 | E18: 6 | F18: 8 | G18: 9 | H18: 12 | I18: 2 | J18: 3 | K18: 9 | L18: =IF(COUNT(E18:K18)=0,"kosong",IF(COUNT(E18:K18)<7,"belum lengkap","OK")) -> OK
A19: P08 | B19: =IF(Setup!$B$18="","",Setup!$B$18) -> Hana | C19: 1 | D19: =Setup!$B$5 -> 527 | E19: 6 | F19: 7 | G19: 12 | H19: 10 | I19: 5 | J19: 6 | K19: 7 | L19: =IF(COUNT(E19:K19)=0,"kosong",IF(COUNT(E19:K19)<7,"belum lengkap","OK")) -> OK
A20: P08 | B20: =IF(Setup!$B$18="","",Setup!$B$18) -> Hana | C20: 2 | D20: =Setup!$B$6 -> 381 | E20: 8 | F20: 11 | G20: 10 | H20: 8 | I20: 6 | J20: 3 | K20: 10 | L20: =IF(COUNT(E20:K20)=0,"kosong",IF(COUNT(E20:K20)<7,"belum lengkap","OK")) -> OK
A21: P09 | B21: =IF(Setup!$B$19="","",Setup!$B$19) -> Indra | C21: 1 | D21: =Setup!$B$5 -> 527 | E21: 10 | F21: 7 | G21: 9 | H21: 7 | I21: 10 | J21: 9 | K21: 12 | L21: =IF(COUNT(E21:K21)=0,"kosong",IF(COUNT(E21:K21)<7,"belum lengkap","OK")) -> OK
A22: P09 | B22: =IF(Setup!$B$19="","",Setup!$B$19) -> Indra | C22: 2 | D22: =Setup!$B$6 -> 381 | E22: 9 | F22: 9 | G22: 7 | H22: 8 | I22: 6 | J22: 5 | K22: 11 | L22: =IF(COUNT(E22:K22)=0,"kosong",IF(COUNT(E22:K22)<7,"belum lengkap","OK")) -> OK
A23: P10 | B23: =IF(Setup!$B$20="","",Setup!$B$20) -> Joko | C23: 1 | D23: =Setup!$B$5 -> 527 | E23: 10 | F23: 8 | G23: 10 | H23: 5 | I23: 12 | J23: 8 | K23: 4 | L23: =IF(COUNT(E23:K23)=0,"kosong",IF(COUNT(E23:K23)<7,"belum lengkap","OK")) -> OK
A24: P10 | B24: =IF(Setup!$B$20="","",Setup!$B$20) -> Joko | C24: 2 | D24: =Setup!$B$6 -> 381 | E24: 8 | F24: 7 | G24: 9 | H24: 8 | I24: 3 | J24: 8 | K24: 10 | L24: =IF(COUNT(E24:K24)=0,"kosong",IF(COUNT(E24:K24)<7,"belum lengkap","OK")) -> OK
A25: P11 | B25: =IF(Setup!$B$21="","",Setup!$B$21) -> Kirana | C25: 1 | D25: =Setup!$B$5 -> 527 | E25: 10 | F25: 8 | G25: 6 | H25: 8 | I25: 12 | J25: 4 | K25: 8 | L25: =IF(COUNT(E25:K25)=0,"kosong",IF(COUNT(E25:K25)<7,"belum lengkap","OK")) -> OK
A26: P11 | B26: =IF(Setup!$B$21="","",Setup!$B$21) -> Kirana | C26: 2 | D26: =Setup!$B$6 -> 381 | E26: 9 | F26: 10 | G26: 11 | H26: 7 | I26: 3 | J26: 4 | K26: 11 | L26: =IF(COUNT(E26:K26)=0,"kosong",IF(COUNT(E26:K26)<7,"belum lengkap","OK")) -> OK
A27: P12 | B27: =IF(Setup!$B$22="","",Setup!$B$22) -> Lutfi | C27: 1 | D27: =Setup!$B$5 -> 527 | E27: 11 | F27: 6 | G27: 6 | H27: 8 | I27: 12 | J27: 7 | K27: 8 | L27: =IF(COUNT(E27:K27)=0,"kosong",IF(COUNT(E27:K27)<7,"belum lengkap","OK")) -> OK
A28: P12 | B28: =IF(Setup!$B$22="","",Setup!$B$22) -> Lutfi | C28: 2 | D28: =Setup!$B$6 -> 381 | E28: 7 | F28: 9 | G28: 10 | H28: 8 | I28: 2 | J28: 4 | K28: 7 | L28: =IF(COUNT(E28:K28)=0,"kosong",IF(COUNT(E28:K28)<7,"belum lengkap","OK")) -> OK
A29: P13 | B29: =IF(Setup!$B$23="","",Setup!$B$23) -> Maya | C29: 1 | D29: =Setup!$B$5 -> 527 | E29: 10 | F29: 6 | G29: 8 | H29: 4 | I29: 12 | J29: 7 | K29: 9 | L29: =IF(COUNT(E29:K29)=0,"kosong",IF(COUNT(E29:K29)<7,"belum lengkap","OK")) -> OK
A30: P13 | B30: =IF(Setup!$B$23="","",Setup!$B$23) -> Maya | C30: 2 | D30: =Setup!$B$6 -> 381 | E30: 7 | F30: 10 | G30: 6 | H30: 8 | I30: 5 | J30: 8 | K30: 11 | L30: =IF(COUNT(E30:K30)=0,"kosong",IF(COUNT(E30:K30)<7,"belum lengkap","OK")) -> OK
A31: P14 | B31: =IF(Setup!$B$24="","",Setup!$B$24) -> Nanda | C31: 1 | D31: =Setup!$B$5 -> 527 | E31: 7 | F31: 8 | G31: 11 | H31: 6 | I31: 10 | J31: 6 | K31: 8 | L31: =IF(COUNT(E31:K31)=0,"kosong",IF(COUNT(E31:K31)<7,"belum lengkap","OK")) -> OK
A32: P14 | B32: =IF(Setup!$B$24="","",Setup!$B$24) -> Nanda | C32: 2 | D32: =Setup!$B$6 -> 381 | E32: 12 | F32: 8 | G32: 10 | H32: 11 | I32: 3 | J32: 5 | K32: 8 | L32: =IF(COUNT(E32:K32)=0,"kosong",IF(COUNT(E32:K32)<7,"belum lengkap","OK")) -> OK
A33: P15 | B33: =IF(Setup!$B$25="","",Setup!$B$25) -> Oki | C33: 1 | D33: =Setup!$B$5 -> 527 | E33: 5 | F33: 10 | G33: 8 | H33: 4 | I33: 10 | J33: 9 | K33: 4 | L33: =IF(COUNT(E33:K33)=0,"kosong",IF(COUNT(E33:K33)<7,"belum lengkap","OK")) -> OK
A34: P15 | B34: =IF(Setup!$B$25="","",Setup!$B$25) -> Oki | C34: 2 | D34: =Setup!$B$6 -> 381 | E34: 10 | F34: 8 | G34: 7 | H34: 8 | I34: 5 | J34: 5 | K34: 4 | L34: =IF(COUNT(E34:K34)=0,"kosong",IF(COUNT(E34:K34)<7,"belum lengkap","OK")) -> OK
A35: P16 | B35: =IF(Setup!$B$26="","",Setup!$B$26) -> Putri | C35: 1 | D35: =Setup!$B$5 -> 527 | E35: 8 | F35: 5 | G35: 10 | H35: 5 | I35: 7 | J35: 6 | K35: 8 | L35: =IF(COUNT(E35:K35)=0,"kosong",IF(COUNT(E35:K35)<7,"belum lengkap","OK")) -> OK
A36: P16 | B36: =IF(Setup!$B$26="","",Setup!$B$26) -> Putri | C36: 2 | D36: =Setup!$B$6 -> 381 | E36: 7 | F36: 12 | G36: 9 | H36: 7 | I36: 6 | J36: 1 | K36: 9 | L36: =IF(COUNT(E36:K36)=0,"kosong",IF(COUNT(E36:K36)<7,"belum lengkap","OK")) -> OK
A37: P17 | B37: =IF(Setup!$B$27="","",Setup!$B$27) -> Raka | C37: 1 | D37: =Setup!$B$5 -> 527 | E37: 7 | F37: 4 | G37: 8 | H37: 7 | I37: 10 | J37: 7 | K37: 9 | L37: =IF(COUNT(E37:K37)=0,"kosong",IF(COUNT(E37:K37)<7,"belum lengkap","OK")) -> OK
A38: P17 | B38: =IF(Setup!$B$27="","",Setup!$B$27) -> Raka | C38: 2 | D38: =Setup!$B$6 -> 381 | E38: 11 | F38: 12 | G38: 10 | H38: 3 | I38: 0 | J38: 4 | K38: 8 | L38: =IF(COUNT(E38:K38)=0,"kosong",IF(COUNT(E38:K38)<7,"belum lengkap","OK")) -> OK
A39: P18 | B39: =IF(Setup!$B$28="","",Setup!$B$28) -> Sari | C39: 1 | D39: =Setup!$B$5 -> 527 | E39: 5 | F39: 11 | G39: 12 | H39: 8 | I39: 10 | J39: 11 | K39: 6 | L39: =IF(COUNT(E39:K39)=0,"kosong",IF(COUNT(E39:K39)<7,"belum lengkap","OK")) -> OK
A40: P18 | B40: =IF(Setup!$B$28="","",Setup!$B$28) -> Sari | C40: 2 | D40: =Setup!$B$6 -> 381 | E40: 6 | F40: 6 | G40: 10 | H40: 6 | I40: 2 | J40: 9 | K40: 9 | L40: =IF(COUNT(E40:K40)=0,"kosong",IF(COUNT(E40:K40)<7,"belum lengkap","OK")) -> OK
...

Sheet CATA
A1: Descriptive Assessment — CATA (SCA-103)
A2: Ketik 1 pada descriptor yang dipilih; biarkan kosong jika tidak. Perhatikan batas jumlah pilihan tiap bagian.
A3: ID Panelis | B3: Nama | C3: Urutan | D3: Kode Sampel | E3: Fragrance / Aroma — pilih maks. 5 | N3: Flavor / Aftertaste — pilih maks. 5 | W3: Main tastes — pilih maks. 2 | AB3: Mouthfeel — pilih maks. 2 | AG3: n FA (maks 5) | AH3: n FL (maks 5) | AI3: n Taste (maks 2) | AJ3: n MF (maks 2) | AK3: Status
E4: Floral | F4: Fruity | G4: Sour/Fermented | H4: Green/Vegetative | I4: Other | J4: Roasted | K4: Nutty/Cocoa | L4: Spicy | M4: Sweet | N4: Floral | O4: Fruity | P4: Sour/Fermented | Q4: Green/Vegetative | R4: Other | S4: Roasted | T4: Nutty/Cocoa | U4: Spicy | V4: Sweet | W4: Salty | X4: Sour | Y4: Sweet | Z4: Bitter | AA4: Umami | AB4: Rough | AC4: Oily | AD4: Smooth | AE4: Mouth-drying | AF4: Metallic
A5: P01 | B5: =IF(Setup!$B$11="","",Setup!$B$11) -> Ayu | C5: 1 | D5: =Setup!$B$5 -> 527 | E5: 1 | F5: 1 | H5: 1 | K5: 1 | M5: 1 | O5: 1 | P5: 1 | T5: 1 | X5: 1 | Z5: 1 | AE5: 1 | AF5: 1 | AG5: =SUM(E5:M5) -> 5 | AH5: =SUM(N5:V5) -> 3 | AI5: =SUM(W5:AA5) -> 2 | AJ5: =SUM(AB5:AF5) -> 2 | AK5: =IF(COUNTA(E5:AF5)=0,"kosong",IF((IF(AG5>5,"n FA>5 ","")&IF(AH5>5,"n FL>5 ","")&IF(AI5>2,"n Taste>2 ","")&IF(AJ5>2,"n MF>2 ",""))="",IF(AG5>5,"n FA>5 ","")&IF(AH5>5,"n FL>5 ","")&IF(AI5>2,"n Taste>2 ","")&IF(AJ5>2,"n MF>2 ","OK"))) -> OK
A6: P01 | B6: =IF(Setup!$B$11="","",Setup!$B$11) -> Ayu | C6: 2 | D6: =Setup!$B$6 -> 381 | J6: 1 | K6: 1 | M6: 1 | O6: 1 | T6: 1 | Z6: 1 | AB6: 1 | AE6: 1 | AG6: =SUM(E6:M6) -> 3 | AH6: =SUM(N6:V6) -> 2 | AI6: =SUM(W6:AA6) -> 1 | AJ6: =SUM(AB6:AF6) -> 2 | AK6: =IF(COUNTA(E6:AF6)=0,"kosong",IF((IF(AG6>5,"n FA>5 ","")&IF(AH6>5,"n FL>5 ","")&IF(AI6>2,"n Taste>2 ","")&IF(AJ6>2,"n MF>2 ",""))="",IF(AG6>5,"n FA>5 ","")&IF(AH6>5,"n FL>5 ","")&IF(AI6>2,"n Taste>2 ","")&IF(AJ6>2,"n MF>2 ","OK"))) -> OK
A7: P02 | B7: =IF(Setup!$B$12="","",Setup!$B$12) -> Bima | C7: 1 | D7: =Setup!$B$5 -> 527 | E7: 1 | F7: 1 | J7: 1 | K7: 1 | M7: 1 | O7: 1 | P7: 1 | U7: 1 | V7: 1 | X7: 1 | AD7: 1 | AG7: =SUM(E7:M7) -> 5 | AH7: =SUM(N7:V7) -> 4 | AI7: =SUM(W7:AA7) -> 1 | AJ7: =SUM(AB7:AF7) -> 1 | AK7: =IF(COUNTA(E7:AF7)=0,"kosong",IF((IF(AG7>5,"n FA>5 ","")&IF(AH7>5,"n FL>5 ","")&IF(AI7>2,"n Taste>2 ","")&IF(AJ7>2,"n MF>2 ",""))="",IF(AG7>5,"n FA>5 ","")&IF(AH7>5,"n FL>5 ","")&IF(AI7>2,"n Taste>2 ","")&IF(AJ7>2,"n MF>2 ","OK"))) -> OK
A8: P02 | B8: =IF(Setup!$B$12="","",Setup!$B$12) -> Bima | C8: 2 | D8: =Setup!$B$6 -> 381 | I8: 1 | J8: 1 | K8: 1 | L8: 1 | P8: 1 | S8: 1 | Y8: 1 | AE8: 1 | AG8: =SUM(E8:M8) -> 4 | AH8: =SUM(N8:V8) -> 2 | AI8: =SUM(W8:AA8) -> 1 | AJ8: =SUM(AB8:AF8) -> 1 | AK8: =IF(COUNTA(E8:AF8)=0,"kosong",IF((IF(AG8>5,"n FA>5 ","")&IF(AH8>5,"n FL>5 ","")&IF(AI8>2,"n Taste>2 ","")&IF(AJ8>2,"n MF>2 ",""))="",IF(AG8>5,"n FA>5 ","")&IF(AH8>5,"n FL>5 ","")&IF(AI8>2,"n Taste>2 ","")&IF(AJ8>2,"n MF>2 ","OK"))) -> OK
A9: P03 | B9: =IF(Setup!$B$13="","",Setup!$B$13) -> Citra | C9: 1 | D9: =Setup!$B$5 -> 527 | F9: 1 | J9: 1 | O9: 1 | P9: 1 | V9: 1 | Y9: 1 | Z9: 1 | AC9: 1 | AG9: =SUM(E9:M9) -> 2 | AH9: =SUM(N9:V9) -> 3 | AI9: =SUM(W9:AA9) -> 2 | AJ9: =SUM(AB9:AF9) -> 1 | AK9: =IF(COUNTA(E9:AF9)=0,"kosong",IF((IF(AG9>5,"n FA>5 ","")&IF(AH9>5,"n FL>5 ","")&IF(AI9>2,"n Taste>2 ","")&IF(AJ9>2,"n MF>2 ",""))="",IF(AG9>5,"n FA>5 ","")&IF(AH9>5,"n FL>5 ","")&IF(AI9>2,"n Taste>2 ","")&IF(AJ9>2,"n MF>2 ","OK"))) -> OK
A10: P03 | B10: =IF(Setup!$B$13="","",Setup!$B$13) -> Citra | C10: 2 | D10: =Setup!$B$6 -> 381 | J10: 1 | Q10: 1 | S10: 1 | T10: 1 | V10: 1 | Z10: 1 | AC10: 1 | AE10: 1 | AG10: =SUM(E10:M10) -> 1 | AH10: =SUM(N10:V10) -> 4 | AI10: =SUM(W10:AA10) -> 1 | AJ10: =SUM(AB10:AF10) -> 2 | AK10: =IF(COUNTA(E10:AF10)=0,"kosong",IF((IF(AG10>5,"n FA>5 ","")&IF(AH10>5,"n FL>5 ","")&IF(AI10>2,"n Taste>2 ","")&IF(AJ10>2,"n MF>2 ",""))="",IF(AG10>5,"n FA>5 ","")&IF(AH10>5,"n FL>5 ","")&IF(AI10>2,"n Taste>2 ","")&IF(AJ10>2,"n MF>2 ","OK"))) -> OK
A11: P04 | B11: =IF(Setup!$B$14="","",Setup!$B$14) -> Dewi | C11: 1 | D11: =Setup!$B$5 -> 527 | E11: 1 | F11: 1 | M11: 1 | N11: 1 | S11: 1 | V11: 1 | Z11: 1 | AG11: =SUM(E11:M11) -> 3 | AH11: =SUM(N11:V11) -> 3 | AI11: =SUM(W11:AA11) -> 1 | AJ11: =SUM(AB11:AF11) -> 0 | AK11: =IF(COUNTA(E11:AF11)=0,"kosong",IF((IF(AG11>5,"n FA>5 ","")&IF(AH11>5,"n FL>5 ","")&IF(AI11>2,"n Taste>2 ","")&IF(AJ11>2,"n MF>2 ",""))="",IF(AG11>5,"n FA>5 ","")&IF(AH11>5,"n FL>5 ","")&IF(AI11>2,"n Taste>2 ","")&IF(AJ11>2,"n MF>2 ","OK"))) -> OK
A12: P04 | B12: =IF(Setup!$B$14="","",Setup!$B$14) -> Dewi | C12: 2 | D12: =Setup!$B$6 -> 381 | J12: 1 | K12: 1 | L12: 1 | P12: 1 | T12: 1 | Z12: 1 | AE12: 1 | AG12: =SUM(E12:M12) -> 3 | AH12: =SUM(N12:V12) -> 2 | AI12: =SUM(W12:AA12) -> 1 | AJ12: =SUM(AB12:AF12) -> 1 | AK12: =IF(COUNTA(E12:AF12)=0,"kosong",IF((IF(AG12>5,"n FA>5 ","")&IF(AH12>5,"n FL>5 ","")&IF(AI12>2,"n Taste>2 ","")&IF(AJ12>2,"n MF>2 ",""))="",IF(AG12>5,"n FA>5 ","")&IF(AH12>5,"n FL>5 ","")&IF(AI12>2,"n Taste>2 ","")&IF(AJ12>2,"n MF>2 ","OK"))) -> OK
A13: P05 | B13: =IF(Setup!$B$15="","",Setup!$B$15) -> Eka | C13: 1 | D13: =Setup!$B$5 -> 527 | E13: 1 | F13: 1 | G13: 1 | M13: 1 | O13: 1 | V13: 1 | X13: 1 | AB13: 1 | AG13: =SUM(E13:M13) -> 4 | AH13: =SUM(N13:V13) -> 2 | AI13: =SUM(W13:AA13) -> 1 | AJ13: =SUM(AB13:AF13) -> 1 | AK13: =IF(COUNTA(E13:AF13)=0,"kosong",IF((IF(AG13>5,"n FA>5 ","")&IF(AH13>5,"n FL>5 ","")&IF(AI13>2,"n Taste>2 ","")&IF(AJ13>2,"n MF>2 ",""))="",IF(AG13>5,"n FA>5 ","")&IF(AH13>5,"n FL>5 ","")&IF(AI13>2,"n Taste>2 ","")&IF(AJ13>2,"n MF>2 ","OK"))) -> OK
A14: P05 | B14: =IF(Setup!$B$15="","",Setup!$B$15) -> Eka | C14: 2 | D14: =Setup!$B$6 -> 381 | G14: 1 | I14: 1 | J14: 1 | K14: 1 | L14: 1 | S14: 1 | Z14: 1 | AA14: 1 | AF14: 1 | AG14: =SUM(E14:M14) -> 5 | AH14: =SUM(N14:V14) -> 1 | AI14: =SUM(W14:AA14) -> 2 | AJ14: =SUM(AB14:AF14) -> 1 | AK14: =IF(COUNTA(E14:AF14)=0,"kosong",IF((IF(AG14>5,"n FA>5 ","")&IF(AH14>5,"n FL>5 ","")&IF(AI14>2,"n Taste>2 ","")&IF(AJ14>2,"n MF>2 ",""))="",IF(AG14>5,"n FA>5 ","")&IF(AH14>5,"n FL>5 ","")&IF(AI14>2,"n Taste>2 ","")&IF(AJ14>2,"n MF>2 ","OK"))) -> OK
A15: P06 | B15: =IF(Setup!$B$16="","",Setup!$B$16) -> Fajar | C15: 1 | D15: =Setup!$B$5 -> 527 | G15: 1 | M15: 1 | O15: 1 | T15: 1 | V15: 1 | Y15: 1 | AB15: 1 | AD15: 1 | AG15: =SUM(E15:M15) -> 2 | AH15: =SUM(N15:V15) -> 3 | AI15: =SUM(W15:AA15) -> 1 | AJ15: =SUM(AB15:AF15) -> 2 | AK15: =IF(COUNTA(E15:AF15)=0,"kosong",IF((IF(AG15>5,"n FA>5 ","")&IF(AH15>5,"n FL>5 ","")&IF(AI15>2,"n Taste>2 ","")&IF(AJ15>2,"n MF>2 ",""))="",IF(AG15>5,"n FA>5 ","")&IF(AH15>5,"n FL>5 ","")&IF(AI15>2,"n Taste>2 ","")&IF(AJ15>2,"n MF>2 ","OK"))) -> OK
A16: P06 | B16: =IF(Setup!$B$16="","",Setup!$B$16) -> Fajar | C16: 2 | D16: =Setup!$B$6 -> 381 | J16: 1 | P16: 1 | R16: 1 | S16: 1 | T16: 1 | Z16: 1 | AE16: 1 | AF16: 1 | AG16: =SUM(E16:M16) -> 1 | AH16: =SUM(N16:V16) -> 4 | AI16: =SUM(W16:AA16) -> 1 | AJ16: =SUM(AB16:AF16) -> 2 | AK16: =IF(COUNTA(E16:AF16)=0,"kosong",IF((IF(AG16>5,"n FA>5 ","")&IF(AH16>5,"n FL>5 ","")&IF(AI16>2,"n Taste>2 ","")&IF(AJ16>2,"n MF>2 ",""))="",IF(AG16>5,"n FA>5 ","")&IF(AH16>5,"n FL>5 ","")&IF(AI16>2,"n Taste>2 ","")&IF(AJ16>2,"n MF>2 ","OK"))) -> OK
A17: P07 | B17: =IF(Setup!$B$17="","",Setup!$B$17) -> Gita | C17: 1 | D17: =Setup!$B$5 -> 527 | E17: 1 | F17: 1 | G17: 1 | H17: 1 | M17: 1 | N17: 1 | O17: 1 | P17: 1 | X17: 1 | Z17: 1 | AD17: 1 | AE17: 1 | AG17: =SUM(E17:M17) -> 5 | AH17: =SUM(N17:V17) -> 3 | AI17: =SUM(W17:AA17) -> 2 | AJ17: =SUM(AB17:AF17) -> 2 | AK17: =IF(COUNTA(E17:AF17)=0,"kosong",IF((IF(AG17>5,"n FA>5 ","")&IF(AH17>5,"n FL>5 ","")&IF(AI17>2,"n Taste>2 ","")&IF(AJ17>2,"n MF>2 ",""))="",IF(AG17>5,"n FA>5 ","")&IF(AH17>5,"n FL>5 ","")&IF(AI17>2,"n Taste>2 ","")&IF(AJ17>2,"n MF>2 ","OK"))) -> OK
A18: P07 | B18: =IF(Setup!$B$17="","",Setup!$B$17) -> Gita | C18: 2 | D18: =Setup!$B$6 -> 381 | H18: 1 | I18: 1 | K18: 1 | L18: 1 | M18: 1 | P18: 1 | S18: 1 | T18: 1 | U18: 1 | Z18: 1 | AC18: 1 | AE18: 1 | AG18: =SUM(E18:M18) -> 5 | AH18: =SUM(N18:V18) -> 4 | AI18: =SUM(W18:AA18) -> 1 | AJ18: =SUM(AB18:AF18) -> 2 | AK18: =IF(COUNTA(E18:AF18)=0,"kosong",IF((IF(AG18>5,"n FA>5 ","")&IF(AH18>5,"n FL>5 ","")&IF(AI18>2,"n Taste>2 ","")&IF(AJ18>2,"n MF>2 ",""))="",IF(AG18>5,"n FA>5 ","")&IF(AH18>5,"n FL>5 ","")&IF(AI18>2,"n Taste>2 ","")&IF(AJ18>2,"n MF>2 ","OK"))) -> OK
A19: P08 | B19: =IF(Setup!$B$18="","",Setup!$B$18) -> Hana | C19: 1 | D19: =Setup!$B$5 -> 527 | E19: 1 | F19: 1 | L19: 1 | M19: 1 | O19: 1 | Y19: 1 | AE19: 1 | AG19: =SUM(E19:M19) -> 4 | AH19: =SUM(N19:V19) -> 1 | AI19: =SUM(W19:AA19) -> 1 | AJ19: =SUM(AB19:AF19) -> 1 | AK19: =IF(COUNTA(E19:AF19)=0,"kosong",IF((IF(AG19>5,"n FA>5 ","")&IF(AH19>5,"n FL>5 ","")&IF(AI19>2,"n Taste>2 ","")&IF(AJ19>2,"n MF>2 ",""))="",IF(AG19>5,"n FA>5 ","")&IF(AH19>5,"n FL>5 ","")&IF(AI19>2,"n Taste>2 ","")&IF(AJ19>2,"n MF>2 ","OK"))) -> OK
A20: P08 | B20: =IF(Setup!$B$18="","",Setup!$B$18) -> Hana | C20: 2 | D20: =Setup!$B$6 -> 381 | J20: 1 | O20: 1 | Q20: 1 | R20: 1 | S20: 1 | T20: 1 | Z20: 1 | AA20: 1 | AC20: 1 | AF20: 1 | AG20: =SUM(E20:M20) -> 1 | AH20: =SUM(N20:V20) -> 5 | AI20: =SUM(W20:AA20) -> 2 | AJ20: =SUM(AB20:AF20) -> 2 | AK20: =IF(COUNTA(E20:AF20)=0,"kosong",IF((IF(AG20>5,"n FA>5 ","")&IF(AH20>5,"n FL>5 ","")&IF(AI20>2,"n Taste>2 ","")&IF(AJ20>2,"n MF>2 ",""))="",IF(AG20>5,"n FA>5 ","")&IF(AH20>5,"n FL>5 ","")&IF(AI20>2,"n Taste>2 ","")&IF(AJ20>2,"n MF>2 ","OK"))) -> OK
A21: P09 | B21: =IF(Setup!$B$19="","",Setup!$B$19) -> Indra | C21: 1 | D21: =Setup!$B$5 -> 527 | E21: 1 | F21: 1 | M21: 1 | O21: 1 | V21: 1 | X21: 1 | AC21: 1 | AE21: 1 | AG21: =SUM(E21:M21) -> 3 | AH21: =SUM(N21:V21) -> 2 | AI21: =SUM(W21:AA21) -> 1 | AJ21: =SUM(AB21:AF21) -> 2 | AK21: =IF(COUNTA(E21:AF21)=0,"kosong",IF((IF(AG21>5,"n FA>5 ","")&IF(AH21>5,"n FL>5 ","")&IF(AI21>2,"n Taste>2 ","")&IF(AJ21>2,"n MF>2 ",""))="",IF(AG21>5,"n FA>5 ","")&IF(AH21>5,"n FL>5 ","")&IF(AI21>2,"n Taste>2 ","")&IF(AJ21>2,"n MF>2 ","OK"))) -> OK
A22: P09 | B22: =IF(Setup!$B$19="","",Setup!$B$19) -> Indra | C22: 2 | D22: =Setup!$B$6 -> 381 | J22: 1 | S22: 1 | T22: 1 | U22: 1 | X22: 1 | Z22: 1 | AC22: 1 | AD22: 1 | AG22: =SUM(E22:M22) -> 1 | AH22: =SUM(N22:V22) -> 3 | AI22: =SUM(W22:AA22) -> 2 | AJ22: =SUM(AB22:AF22) -> 2 | AK22: =IF(COUNTA(E22:AF22)=0,"kosong",IF((IF(AG22>5,"n FA>5 ","")&IF(AH22>5,"n FL>5 ","")&IF(AI22>2,"n Taste>2 ","")&IF(AJ22>2,"n MF>2 ",""))="",IF(AG22>5,"n FA>5 ","")&IF(AH22>5,"n FL>5 ","")&IF(AI22>2,"n Taste>2 ","")&IF(AJ22>2,"n MF>2 ","OK"))) -> OK
A23: P10 | B23: =IF(Setup!$B$20="","",Setup!$B$20) -> Joko | C23: 1 | D23: =Setup!$B$5 -> 527 | E23: 1 | F23: 1 | H23: 1 | M23: 1 | N23: 1 | O23: 1 | V23: 1 | X23: 1 | AD23: 1 | AE23: 1 | AG23: =SUM(E23:M23) -> 4 | AH23: =SUM(N23:V23) -> 3 | AI23: =SUM(W23:AA23) -> 1 | AJ23: =SUM(AB23:AF23) -> 2 | AK23: =IF(COUNTA(E23:AF23)=0,"kosong",IF((IF(AG23>5,"n FA>5 ","")&IF(AH23>5,"n FL>5 ","")&IF(AI23>2,"n Taste>2 ","")&IF(AJ23>2,"n MF>2 ",""))="",IF(AG23>5,"n FA>5 ","")&IF(AH23>5,"n FL>5 ","")&IF(AI23>2,"n Taste>2 ","")&IF(AJ23>2,"n MF>2 ","OK"))) -> OK
A24: P10 | B24: =IF(Setup!$B$20="","",Setup!$B$20) -> Joko | C24: 2 | D24: =Setup!$B$6 -> 381 | J24: 1 | K24: 1 | L24: 1 | M24: 1 | R24: 1 | S24: 1 | U24: 1 | Z24: 1 | AB24: 1 | AC24: 1 | AG24: =SUM(E24:M24) -> 4 | AH24: =SUM(N24:V24) -> 3 | AI24: =SUM(W24:AA24) -> 1 | AJ24: =SUM(AB24:AF24) -> 2 | AK24: =IF(COUNTA(E24:AF24)=0,"kosong",IF((IF(AG24>5,"n FA>5 ","")&IF(AH24>5,"n FL>5 ","")&IF(AI24>2,"n Taste>2 ","")&IF(AJ24>2,"n MF>2 ",""))="",IF(AG24>5,"n FA>5 ","")&IF(AH24>5,"n FL>5 ","")&IF(AI24>2,"n Taste>2 ","")&IF(AJ24>2,"n MF>2 ","OK"))) -> OK
A25: P11 | B25: =IF(Setup!$B$21="","",Setup!$B$21) -> Kirana | C25: 1 | D25: =Setup!$B$5 -> 527 | E25: 1 | F25: 1 | G25: 1 | L25: 1 | T25: 1 | Y25: 1 | AD25: 1 | AG25: =SUM(E25:M25) -> 4 | AH25: =SUM(N25:V25) -> 1 | AI25: =SUM(W25:AA25) -> 1 | AJ25: =SUM(AB25:AF25) -> 1 | AK25: =IF(COUNTA(E25:AF25)=0,"kosong",IF((IF(AG25>5,"n FA>5 ","")&IF(AH25>5,"n FL>5 ","")&IF(AI25>2,"n Taste>2 ","")&IF(AJ25>2,"n MF>2 ",""))="",IF(AG25>5,"n FA>5 ","")&IF(AH25>5,"n FL>5 ","")&IF(AI25>2,"n Taste>2 ","")&IF(AJ25>2,"n MF>2 ","OK"))) -> OK
A26: P11 | B26: =IF(Setup!$B$21="","",Setup!$B$21) -> Kirana | C26: 2 | D26: =Setup!$B$6 -> 381 | J26: 1 | K26: 1 | L26: 1 | P26: 1 | S26: 1 | U26: 1 | V26: 1 | Y26: 1 | Z26: 1 | AB26: 1 | AG26: =SUM(E26:M26) -> 3 | AH26: =SUM(N26:V26) -> 4 | AI26: =SUM(W26:AA26) -> 2 | AJ26: =SUM(AB26:AF26) -> 1 | AK26: =IF(COUNTA(E26:AF26)=0,"kosong",IF((IF(AG26>5,"n FA>5 ","")&IF(AH26>5,"n FL>5 ","")&IF(AI26>2,"n Taste>2 ","")&IF(AJ26>2,"n MF>2 ",""))="",IF(AG26>5,"n FA>5 ","")&IF(AH26>5,"n FL>5 ","")&IF(AI26>2,"n Taste>2 ","")&IF(AJ26>2,"n MF>2 ","OK"))) -> OK
A27: P12 | B27: =IF(Setup!$B$22="","",Setup!$B$22) -> Lutfi | C27: 1 | D27: =Setup!$B$5 -> 527 | E27: 1 | F27: 1 | G27: 1 | K27: 1 | O27: 1 | P27: 1 | U27: 1 | X27: 1 | AD27: 1 | AE27: 1 | AG27: =SUM(E27:M27) -> 4 | AH27: =SUM(N27:V27) -> 3 | AI27: =SUM(W27:AA27) -> 1 | AJ27: =SUM(AB27:AF27) -> 2 | AK27: =IF(COUNTA(E27:AF27)=0,"kosong",IF((IF(AG27>5,"n FA>5 ","")&IF(AH27>5,"n FL>5 ","")&IF(AI27>2,"n Taste>2 ","")&IF(AJ27>2,"n MF>2 ",""))="",IF(AG27>5,"n FA>5 ","")&IF(AH27>5,"n FL>5 ","")&IF(AI27>2,"n Taste>2 ","")&IF(AJ27>2,"n MF>2 ","OK"))) -> OK
A28: P12 | B28: =IF(Setup!$B$22="","",Setup!$B$22) -> Lutfi | C28: 2 | D28: =Setup!$B$6 -> 381 | H28: 1 | K28: 1 | S28: 1 | T28: 1 | V28: 1 | X28: 1 | Z28: 1 | AC28: 1 | AG28: =SUM(E28:M28) -> 2 | AH28: =SUM(N28:V28) -> 3 | AI28: =SUM(W28:AA28) -> 2 | AJ28: =SUM(AB28:AF28) -> 1 | AK28: =IF(COUNTA(E28:AF28)=0,"kosong",IF((IF(AG28>5,"n FA>5 ","")&IF(AH28>5,"n FL>5 ","")&IF(AI28>2,"n Taste>2 ","")&IF(AJ28>2,"n MF>2 ",""))="",IF(AG28>5,"n FA>5 ","")&IF(AH28>5,"n FL>5 ","")&IF(AI28>2,"n Taste>2 ","")&IF(AJ28>2,"n MF>2 ","OK"))) -> OK
A29: P13 | B29: =IF(Setup!$B$23="","",Setup!$B$23) -> Maya | C29: 1 | D29: =Setup!$B$5 -> 527 | F29: 1 | H29: 1 | M29: 1 | N29: 1 | O29: 1 | P29: 1 | Q29: 1 | X29: 1 | Y29: 1 | AD29: 1 | AF29: 1 | AG29: =SUM(E29:M29) -> 3 | AH29: =SUM(N29:V29) -> 4 | AI29: =SUM(W29:AA29) -> 2 | AJ29: =SUM(AB29:AF29) -> 2 | AK29: =IF(COUNTA(E29:AF29)=0,"kosong",IF((IF(AG29>5,"n FA>5 ","")&IF(AH29>5,"n FL>5 ","")&IF(AI29>2,"n Taste>2 ","")&IF(AJ29>2,"n MF>2 ",""))="",IF(AG29>5,"n FA>5 ","")&IF(AH29>5,"n FL>5 ","")&IF(AI29>2,"n Taste>2 ","")&IF(AJ29>2,"n MF>2 ","OK"))) -> OK
A30: P13 | B30: =IF(Setup!$B$23="","",Setup!$B$23) -> Maya | C30: 2 | D30: =Setup!$B$6 -> 381 | J30: 1 | K30: 1 | L30: 1 | O30: 1 | S30: 1 | T30: 1 | U30: 1 | Z30: 1 | AE30: 1 | AG30: =SUM(E30:M30) -> 3 | AH30: =SUM(N30:V30) -> 4 | AI30: =SUM(W30:AA30) -> 1 | AJ30: =SUM(AB30:AF30) -> 1 | AK30: =IF(COUNTA(E30:AF30)=0,"kosong",IF((IF(AG30>5,"n FA>5 ","")&IF(AH30>5,"n FL>5 ","")&IF(AI30>2,"n Taste>2 ","")&IF(AJ30>2,"n MF>2 ",""))="",IF(AG30>5,"n FA>5 ","")&IF(AH30>5,"n FL>5 ","")&IF(AI30>2,"n Taste>2 ","")&IF(AJ30>2,"n MF>2 ","OK"))) -> OK
A31: P14 | B31: =IF(Setup!$B$24="","",Setup!$B$24) -> Nanda | C31: 1 | D31: =Setup!$B$5 -> 527 | F31: 1 | M31: 1 | O31: 1 | P31: 1 | V31: 1 | X31: 1 | AD31: 1 | AG31: =SUM(E31:M31) -> 2 | AH31: =SUM(N31:V31) -> 3 | AI31: =SUM(W31:AA31) -> 1 | AJ31: =SUM(AB31:AF31) -> 1 | AK31: =IF(COUNTA(E31:AF31)=0,"kosong",IF((IF(AG31>5,"n FA>5 ","")&IF(AH31>5,"n FL>5 ","")&IF(AI31>2,"n Taste>2 ","")&IF(AJ31>2,"n MF>2 ",""))="",IF(AG31>5,"n FA>5 ","")&IF(AH31>5,"n FL>5 ","")&IF(AI31>2,"n Taste>2 ","")&IF(AJ31>2,"n MF>2 ","OK"))) -> OK
A32: P14 | B32: =IF(Setup!$B$24="","",Setup!$B$24) -> Nanda | C32: 2 | D32: =Setup!$B$6 -> 381 | H32: 1 | J32: 1 | L32: 1 | R32: 1 | S32: 1 | T32: 1 | AA32: 1 | AB32: 1 | AC32: 1 | AG32: =SUM(E32:M32) -> 3 | AH32: =SUM(N32:V32) -> 3 | AI32: =SUM(W32:AA32) -> 1 | AJ32: =SUM(AB32:AF32) -> 2 | AK32: =IF(COUNTA(E32:AF32)=0,"kosong",IF((IF(AG32>5,"n FA>5 ","")&IF(AH32>5,"n FL>5 ","")&IF(AI32>2,"n Taste>2 ","")&IF(AJ32>2,"n MF>2 ",""))="",IF(AG32>5,"n FA>5 ","")&IF(AH32>5,"n FL>5 ","")&IF(AI32>2,"n Taste>2 ","")&IF(AJ32>2,"n MF>2 ","OK"))) -> OK
A33: P15 | B33: =IF(Setup!$B$25="","",Setup!$B$25) -> Oki | C33: 1 | D33: =Setup!$B$5 -> 527 | F33: 1 | G33: 1 | O33: 1 | T33: 1 | X33: 1 | AD33: 1 | AG33: =SUM(E33:M33) -> 2 | AH33: =SUM(N33:V33) -> 2 | AI33: =SUM(W33:AA33) -> 1 | AJ33: =SUM(AB33:AF33) -> 1 | AK33: =IF(COUNTA(E33:AF33)=0,"kosong",IF((IF(AG33>5,"n FA>5 ","")&IF(AH33>5,"n FL>5 ","")&IF(AI33>2,"n Taste>2 ","")&IF(AJ33>2,"n MF>2 ",""))="",IF(AG33>5,"n FA>5 ","")&IF(AH33>5,"n FL>5 ","")&IF(AI33>2,"n Taste>2 ","")&IF(AJ33>2,"n MF>2 ","OK"))) -> OK
A34: P15 | B34: =IF(Setup!$B$25="","",Setup!$B$25) -> Oki | C34: 2 | D34: =Setup!$B$6 -> 381 | J34: 1 | K34: 1 | N34: 1 | S34: 1 | T34: 1 | Z34: 1 | AC34: 1 | AE34: 1 | AG34: =SUM(E34:M34) -> 2 | AH34: =SUM(N34:V34) -> 3 | AI34: =SUM(W34:AA34) -> 1 | AJ34: =SUM(AB34:AF34) -> 2 | AK34: =IF(COUNTA(E34:AF34)=0,"kosong",IF((IF(AG34>5,"n FA>5 ","")&IF(AH34>5,"n FL>5 ","")&IF(AI34>2,"n Taste>2 ","")&IF(AJ34>2,"n MF>2 ",""))="",IF(AG34>5,"n FA>5 ","")&IF(AH34>5,"n FL>5 ","")&IF(AI34>2,"n Taste>2 ","")&IF(AJ34>2,"n MF>2 ","OK"))) -> OK
A35: P16 | B35: =IF(Setup!$B$26="","",Setup!$B$26) -> Putri | C35: 1 | D35: =Setup!$B$5 -> 527 | F35: 1 | G35: 1 | H35: 1 | M35: 1 | N35: 1 | O35: 1 | P35: 1 | T35: 1 | X35: 1 | AD35: 1 | AE35: 1 | AG35: =SUM(E35:M35) -> 4 | AH35: =SUM(N35:V35) -> 4 | AI35: =SUM(W35:AA35) -> 1 | AJ35: =SUM(AB35:AF35) -> 2 | AK35: =IF(COUNTA(E35:AF35)=0,"kosong",IF((IF(AG35>5,"n FA>5 ","")&IF(AH35>5,"n FL>5 ","")&IF(AI35>2,"n Taste>2 ","")&IF(AJ35>2,"n MF>2 ",""))="",IF(AG35>5,"n FA>5 ","")&IF(AH35>5,"n FL>5 ","")&IF(AI35>2,"n Taste>2 ","")&IF(AJ35>2,"n MF>2 ","OK"))) -> OK
A36: P16 | B36: =IF(Setup!$B$26="","",Setup!$B$26) -> Putri | C36: 2 | D36: =Setup!$B$6 -> 381 | J36: 1 | S36: 1 | Y36: 1 | Z36: 1 | AE36: 1 | AG36: =SUM(E36:M36) -> 1 | AH36: =SUM(N36:V36) -> 1 | AI36: =SUM(W36:AA36) -> 2 | AJ36: =SUM(AB36:AF36) -> 1 | AK36: =IF(COUNTA(E36:AF36)=0,"kosong",IF((IF(AG36>5,"n FA>5 ","")&IF(AH36>5,"n FL>5 ","")&IF(AI36>2,"n Taste>2 ","")&IF(AJ36>2,"n MF>2 ",""))="",IF(AG36>5,"n FA>5 ","")&IF(AH36>5,"n FL>5 ","")&IF(AI36>2,"n Taste>2 ","")&IF(AJ36>2,"n MF>2 ","OK"))) -> OK
A37: P17 | B37: =IF(Setup!$B$27="","",Setup!$B$27) -> Raka | C37: 1 | D37: =Setup!$B$5 -> 527 | F37: 1 | I37: 1 | M37: 1 | O37: 1 | R37: 1 | X37: 1 | Y37: 1 | AD37: 1 | AG37: =SUM(E37:M37) -> 3 | AH37: =SUM(N37:V37) -> 2 | AI37: =SUM(W37:AA37) -> 2 | AJ37: =SUM(AB37:AF37) -> 1 | AK37: =IF(COUNTA(E37:AF37)=0,"kosong",IF((IF(AG37>5,"n FA>5 ","")&IF(AH37>5,"n FL>5 ","")&IF(AI37>2,"n Taste>2 ","")&IF(AJ37>2,"n MF>2 ",""))="",IF(AG37>5,"n FA>5 ","")&IF(AH37>5,"n FL>5 ","")&IF(AI37>2,"n Taste>2 ","")&IF(AJ37>2,"n MF>2 ","OK"))) -> OK
A38: P17 | B38: =IF(Setup!$B$27="","",Setup!$B$27) -> Raka | C38: 2 | D38: =Setup!$B$6 -> 381 | J38: 1 | K38: 1 | S38: 1 | T38: 1 | U38: 1 | Z38: 1 | AB38: 1 | AC38: 1 | AG38: =SUM(E38:M38) -> 2 | AH38: =SUM(N38:V38) -> 3 | AI38: =SUM(W38:AA38) -> 1 | AJ38: =SUM(AB38:AF38) -> 2 | AK38: =IF(COUNTA(E38:AF38)=0,"kosong",IF((IF(AG38>5,"n FA>5 ","")&IF(AH38>5,"n FL>5 ","")&IF(AI38>2,"n Taste>2 ","")&IF(AJ38>2,"n MF>2 ",""))="",IF(AG38>5,"n FA>5 ","")&IF(AH38>5,"n FL>5 ","")&IF(AI38>2,"n Taste>2 ","")&IF(AJ38>2,"n MF>2 ","OK"))) -> OK
A39: P18 | B39: =IF(Setup!$B$28="","",Setup!$B$28) -> Sari | C39: 1 | D39: =Setup!$B$5 -> 527 | E39: 1 | G39: 1 | M39: 1 | N39: 1 | O39: 1 | P39: 1 | X39: 1 | Y39: 1 | AD39: 1 | AG39: =SUM(E39:M39) -> 3 | AH39: =SUM(N39:V39) -> 3 | AI39: =SUM(W39:AA39) -> 2 | AJ39: =SUM(AB39:AF39) -> 1 | AK39: =IF(COUNTA(E39:AF39)=0,"kosong",IF((IF(AG39>5,"n FA>5 ","")&IF(AH39>5,"n FL>5 ","")&IF(AI39>2,"n Taste>2 ","")&IF(AJ39>2,"n MF>2 ",""))="",IF(AG39>5,"n FA>5 ","")&IF(AH39>5,"n FL>5 ","")&IF(AI39>2,"n Taste>2 ","")&IF(AJ39>2,"n MF>2 ","OK"))) -> OK
A40: P18 | B40: =IF(Setup!$B$28="","",Setup!$B$28) -> Sari | C40: 2 | D40: =Setup!$B$6 -> 381 | G40: 1 | J40: 1 | K40: 1 | L40: 1 | Q40: 1 | S40: 1 | T40: 1 | Z40: 1 | AG40: =SUM(E40:M40) -> 4 | AH40: =SUM(N40:V40) -> 3 | AI40: =SUM(W40:AA40) -> 1 | AJ40: =SUM(AB40:AF40) -> 0 | AK40: =IF(COUNTA(E40:AF40)=0,"kosong",IF((IF(AG40>5,"n FA>5 ","")&IF(AH40>5,"n FL>5 ","")&IF(AI40>2,"n Taste>2 ","")&IF(AJ40>2,"n MF>2 ",""))="",IF(AG40>5,"n FA>5 ","")&IF(AH40>5,"n FL>5 ","")&IF(AI40>2,"n Taste>2 ","")&IF(AJ40>2,"n MF>2 ","OK"))) -> OK
...

Sheet R_CATA
A1: Panelis | B1: Urutan | C1: Sampel | D1: Kopi | E1: Terisi | F1: FA_Floral | G1: FA_Fruity | H1: FA_SourFermented | I1: FA_GreenVegetative | J1: FA_Other | K1: FA_Roasted | L1: FA_NuttyCocoa | M1: FA_Spicy | N1: FA_Sweet | O1: FL_Floral | P1: FL_Fruity | Q1: FL_SourFermented | R1: FL_GreenVegetative | S1: FL_Other | T1: FL_Roasted | U1: FL_NuttyCocoa | V1: FL_Spicy | W1: FL_Sweet | X1: TS_Salty | Y1: TS_Sour | Z1: TS_Sweet | AA1: TS_Bitter | AB1: TS_Umami | AC1: MF_Rough | AD1: MF_Oily | AE1: MF_Smooth | AF1: MF_Mouthdrying | AG1: MF_Metallic
A2: =CATA!A5 -> P01 | B2: =CATA!C5 -> 1 | C2: =CATA!D5 -> 527 | D2: =IF(C2=Setup!$B$5,Setup!$C$5,Setup!$C$6) -> Ethiopia natural (light roast) | E2: =IF(COUNTA(CATA!E5:AF5)>0,1,0) -> 1 | F2: =IF(CATA!E5=1,1,0) -> 1 | G2: =IF(CATA!F5=1,1,0) -> 1 | H2: =IF(CATA!G5=1,1,0) -> 0 | I2: =IF(CATA!H5=1,1,0) -> 1 | J2: =IF(CATA!I5=1,1,0) -> 0 | K2: =IF(CATA!J5=1,1,0) -> 0 | L2: =IF(CATA!K5=1,1,0) -> 1 | M2: =IF(CATA!L5=1,1,0) -> 0 | ... AG2: =IF(CATA!AF5=1,1,0) -> 1
A3: =CATA!A6 -> P01 | B3: =CATA!C6 -> 2 | C3: =CATA!D6 -> 381 | D3: =IF(C3=Setup!$B$5,Setup!$C$5,Setup!$C$6) -> Robusta Temanggung (dark roast) | E3: =IF(COUNTA(CATA!E6:AF6)>0,1,0) -> 1 | F3: =IF(CATA!E6=1,1,0) -> 0 | G3: =IF(CATA!F6=1,1,0) -> 0 | H3: =IF(CATA!G6=1,1,0) -> 0 | I3: =IF(CATA!H6=1,1,0) -> 0 | J3: =IF(CATA!I6=1,1,0) -> 0 | K3: =IF(CATA!J6=1,1,0) -> 1 | L3: =IF(CATA!K6=1,1,0) -> 1 | M3: =IF(CATA!L6=1,1,0) -> 0 | ... AG3: =IF(CATA!AF6=1,1,0) -> 0
A4: =CATA!A7 -> P02 | B4: =CATA!C7 -> 1 | C4: =CATA!D7 -> 527 | D4: =IF(C4=Setup!$B$5,Setup!$C$5,Setup!$C$6) -> Ethiopia natural (light roast) | E4: =IF(COUNTA(CATA!E7:AF7)>0,1,0) -> 1 | F4: =IF(CATA!E7=1,1,0) -> 1 | G4: =IF(CATA!F7=1,1,0) -> 1 | H4: =IF(CATA!G7=1,1,0) -> 0 | I4: =IF(CATA!H7=1,1,0) -> 0 | J4: =IF(CATA!I7=1,1,0) -> 0 | K4: =IF(CATA!J7=1,1,0) -> 1 | L4: =IF(CATA!K7=1,1,0) -> 1 | M4: =IF(CATA!L7=1,1,0) -> 0 | ... AG4: =IF(CATA!AF7=1,1,0) -> 0
A5: =CATA!A8 -> P02 | B5: =CATA!C8 -> 2 | C5: =CATA!D8 -> 381 | D5: =IF(C5=Setup!$B$5,Setup!$C$5,Setup!$C$6) -> Robusta Temanggung (dark roast) | E5: =IF(COUNTA(CATA!E8:AF8)>0,1,0) -> 1 | F5: =IF(CATA!E8=1,1,0) -> 0 | G5: =IF(CATA!F8=1,1,0) -> 0 | H5: =IF(CATA!G8=1,1,0) -> 0 | I5: =IF(CATA!H8=1,1,0) -> 0 | J5: =IF(CATA!I8=1,1,0) -> 1 | K5: =IF(CATA!J8=1,1,0) -> 1 | L5: =IF(CATA!K8=1,1,0) -> 1 | M5: =IF(CATA!L8=1,1,0) -> 1 | ... AG5: =IF(CATA!AF8=1,1,0) -> 0
A6: =CATA!A9 -> P03 | B6: =CATA!C9 -> 1 | C6: =CATA!D9 -> 527 | D6: =IF(C6=Setup!$B$5,Setup!$C$5,Setup!$C$6) -> Ethiopia natural (light roast) | E6: =IF(COUNTA(CATA!E9:AF9)>0,1,0) -> 1 | F6: =IF(CATA!E9=1,1,0) -> 0 | G6: =IF(CATA!F9=1,1,0) -> 1 | H6: =IF(CATA!G9=1,1,0) -> 0 | I6: =IF(CATA!H9=1,1,0) -> 0 | J6: =IF(CATA!I9=1,1,0) -> 0 | K6: =IF(CATA!J9=1,1,0) -> 1 | L6: =IF(CATA!K9=1,1,0) -> 0 | M6: =IF(CATA!L9=1,1,0) -> 0 | ... AG6: =IF(CATA!AF9=1,1,0) -> 0
A7: =CATA!A10 -> P03 | B7: =CATA!C10 -> 2 | C7: =CATA!D10 -> 381 | D7: =IF(C7=Setup!$B$5,Setup!$C$5,Setup!$C$6) -> Robusta Temanggung (dark roast) | E7: =IF(COUNTA(CATA!E10:AF10)>0,1,0) -> 1 | F7: =IF(CATA!E10=1,1,0) -> 0 | G7: =IF(CATA!F10=1,1,0) -> 0 | H7: =IF(CATA!G10=1,1,0) -> 0 | I7: =IF(CATA!H10=1,1,0) -> 0 | J7: =IF(CATA!I10=1,1,0) -> 0 | K7: =IF(CATA!J10=1,1,0) -> 1 | L7: =IF(CATA!K10=1,1,0) -> 0 | M7: =IF(CATA!L10=1,1,0) -> 0 | ... AG7: =IF(CATA!AF10=1,1,0) -> 0
A8: =CATA!A11 -> P04 | B8: =CATA!C11 -> 1 | C8: =CATA!D11 -> 527 | D8: =IF(C8=Setup!$B$5,Setup!$C$5,Setup!$C$6) -> Ethiopia natural (light roast) | E8: =IF(COUNTA(CATA!E11:AF11)>0,1,0) -> 1 | F8: =IF(CATA!E11=1,1,0) -> 1 | G8: =IF(CATA!F11=1,1,0) -> 1 | H8: =IF(CATA!G11=1,1,0) -> 0 | I8: =IF(CATA!H11=1,1,0) -> 0 | J8: =IF(CATA!I11=1,1,0) -> 0 | K8: =IF(CATA!J11=1,1,0) -> 0 | L8: =IF(CATA!K11=1,1,0) -> 0 | M8: =IF(CATA!L11=1,1,0) -> 0 | ... AG8: =IF(CATA!AF11=1,1,0) -> 0
A9: =CATA!A12 -> P04 | B9: =CATA!C12 -> 2 | C9: =CATA!D12 -> 381 | D9: =IF(C9=Setup!$B$5,Setup!$C$5,Setup!$C$6) -> Robusta Temanggung (dark roast) | E9: =IF(COUNTA(CATA!E12:AF12)>0,1,0) -> 1 | F9: =IF(CATA!E12=1,1,0) -> 0 | G9: =IF(CATA!F12=1,1,0) -> 0 | H9: =IF(CATA!G12=1,1,0) -> 0 | I9: =IF(CATA!H12=1,1,0) -> 0 | J9: =IF(CATA!I12=1,1,0) -> 0 | K9: =IF(CATA!J12=1,1,0) -> 1 | L9: =IF(CATA!K12=1,1,0) -> 1 | M9: =IF(CATA!L12=1,1,0) -> 1 | ... AG9: =IF(CATA!AF12=1,1,0) -> 0
A10: =CATA!A13 -> P05 | B10: =CATA!C13 -> 1 | C10: =CATA!D13 -> 527 | D10: =IF(C10=Setup!$B$5,Setup!$C$5,Setup!$C$6) -> Ethiopia natural (light roast) | E10: =IF(COUNTA(CATA!E13:AF13)>0,1,0) -> 1 | F10: =IF(CATA!E13=1,1,0) -> 1 | G10: =IF(CATA!F13=1,1,0) -> 1 | H10: =IF(CATA!G13=1,1,0) -> 1 | I10: =IF(CATA!H13=1,1,0) -> 0 | J10: =IF(CATA!I13=1,1,0) -> 0 | K10: =IF(CATA!J13=1,1,0) -> 0 | L10: =IF(CATA!K13=1,1,0) -> 0 | M10: =IF(CATA!L13=1,1,0) -> 0 | ... AG10: =IF(CATA!AF13=1,1,0) -> 0
A11: =CATA!A14 -> P05 | B11: =CATA!C14 -> 2 | C11: =CATA!D14 -> 381 | D11: =IF(C11=Setup!$B$5,Setup!$C$5,Setup!$C$6) -> Robusta Temanggung (dark roast) | E11: =IF(COUNTA(CATA!E14:AF14)>0,1,0) -> 1 | F11: =IF(CATA!E14=1,1,0) -> 0 | G11: =IF(CATA!F14=1,1,0) -> 0 | H11: =IF(CATA!G14=1,1,0) -> 1 | I11: =IF(CATA!H14=1,1,0) -> 0 | J11: =IF(CATA!I14=1,1,0) -> 1 | K11: =IF(CATA!J14=1,1,0) -> 1 | L11: =IF(CATA!K14=1,1,0) -> 1 | M11: =IF(CATA!L14=1,1,0) -> 1 | ... AG11: =IF(CATA!AF14=1,1,0) -> 1
A12: =CATA!A15 -> P06 | B12: =CATA!C15 -> 1 | C12: =CATA!D15 -> 527 | D12: =IF(C12=Setup!$B$5,Setup!$C$5,Setup!$C$6) -> Ethiopia natural (light roast) | E12: =IF(COUNTA(CATA!E15:AF15)>0,1,0) -> 1 | F12: =IF(CATA!E15=1,1,0) -> 0 | G12: =IF(CATA!F15=1,1,0) -> 0 | H12: =IF(CATA!G15=1,1,0) -> 1 | I12: =IF(CATA!H15=1,1,0) -> 0 | J12: =IF(CATA!I15=1,1,0) -> 0 | K12: =IF(CATA!J15=1,1,0) -> 0 | L12: =IF(CATA!K15=1,1,0) -> 0 | M12: =IF(CATA!L15=1,1,0) -> 0 | ... AG12: =IF(CATA!AF15=1,1,0) -> 0
A13: =CATA!A16 -> P06 | B13: =CATA!C16 -> 2 | C13: =CATA!D16 -> 381 | D13: =IF(C13=Setup!$B$5,Setup!$C$5,Setup!$C$6) -> Robusta Temanggung (dark roast) | E13: =IF(COUNTA(CATA!E16:AF16)>0,1,0) -> 1 | F13: =IF(CATA!E16=1,1,0) -> 0 | G13: =IF(CATA!F16=1,1,0) -> 0 | H13: =IF(CATA!G16=1,1,0) -> 0 | I13: =IF(CATA!H16=1,1,0) -> 0 | J13: =IF(CATA!I16=1,1,0) -> 0 | K13: =IF(CATA!J16=1,1,0) -> 1 | L13: =IF(CATA!K16=1,1,0) -> 0 | M13: =IF(CATA!L16=1,1,0) -> 0 | ... AG13: =IF(CATA!AF16=1,1,0) -> 1
... A61: =CATA!A64 -> P30 | B61: =CATA!C64 -> 2 | C61: =CATA!D64 -> 381 | D61: =IF(C61=Setup!$B$5,Setup!$C$5,Setup!$C$6) -> Robusta Temanggung (dark roast) | E61: =IF(COUNTA(CATA!E64:AF64)>0,1,0) -> 1 | F61: =IF(CATA!E64=1,1,0) -> 0 | G61: =IF(CATA!F64=1,1,0) -> 1 | H61: =IF(CATA!G64=1,1,0) -> 0 | I61: =IF(CATA!H64=1,1,0) -> 0 | J61: =IF(CATA!I64=1,1,0) -> 1 | K61: =IF(CATA!J64=1,1,0) -> 1 | L61: =IF(CATA!K64=1,1,0) -> 1 | M61: =IF(CATA!L64=1,1,0) -> 1 | ... AG61: =IF(CATA!AF64=1,1,0) -> 0

Sheet R_Deskriptif
A1: Panelis | B1: Urutan | C1: Sampel | D1: Kopi | E1: Terisi | F1: Fragrance | G1: Aroma | H1: Flavor | I1: Aftertaste | J1: Acidity | K1: Sweetness | L1: Mouthfeel
A2: =Deskriptif!A5 -> P01 | B2: =Deskriptif!C5 -> 1 | C2: =Deskriptif!D5 -> 527 | D2: =IF(C2=Setup!$B$5,Setup!$C$5,Setup!$C$6) -> Ethiopia natural (light roast) | E2: =IF(COUNTA(Deskriptif!E5:K5)>0,1,0) -> 1 | F2: =IF(Deskriptif!E5="","",Deskriptif!E5) -> 7 | G2: =IF(Deskriptif!F5="","",Deskriptif!F5) -> 10 | H2: =IF(Deskriptif!G5="","",Deskriptif!G5) -> 7 | I2: =IF(Deskriptif!H5="","",Deskriptif!H5) -> 7 | J2: =IF(Deskriptif!I5="","",Deskriptif!I5) -> 11 | K2: =IF(Deskriptif!J5="","",Deskriptif!J5) -> 4 | L2: =IF(Deskriptif!K5="","",Deskriptif!K5) -> 7
A3: =Deskriptif!A6 -> P01 | B3: =Deskriptif!C6 -> 2 | C3: =Deskriptif!D6 -> 381 | D3: =IF(C3=Setup!$B$5,Setup!$C$5,Setup!$C$6) -> Robusta Temanggung (dark roast) | E3: =IF(COUNTA(Deskriptif!E6:K6)>0,1,0) -> 1 | F3: =IF(Deskriptif!E6="","",Deskriptif!E6) -> 13 | G3: =IF(Deskriptif!F6="","",Deskriptif!F6) -> 7 | H3: =IF(Deskriptif!G6="","",Deskriptif!G6) -> 10 | I3: =IF(Deskriptif!H6="","",Deskriptif!H6) -> 11 | J3: =IF(Deskriptif!I6="","",Deskriptif!I6) -> 2 | K3: =IF(Deskriptif!J6="","",Deskriptif!J6) -> 6 | L3: =IF(Deskriptif!K6="","",Deskriptif!K6) -> 8
A4: =Deskriptif!A7 -> P02 | B4: =Deskriptif!C7 -> 1 | C4: =Deskriptif!D7 -> 527 | D4: =IF(C4=Setup!$B$5,Setup!$C$5,Setup!$C$6) -> Ethiopia natural (light roast) | E4: =IF(COUNTA(Deskriptif!E7:K7)>0,1,0) -> 1 | F4: =IF(Deskriptif!E7="","",Deskriptif!E7) -> 6 | G4: =IF(Deskriptif!F7="","",Deskriptif!F7) -> 7 | H4: =IF(Deskriptif!G7="","",Deskriptif!G7) -> 10 | I4: =IF(Deskriptif!H7="","",Deskriptif!H7) -> 7 | J4: =IF(Deskriptif!I7="","",Deskriptif!I7) -> 11 | K4: =IF(Deskriptif!J7="","",Deskriptif!J7) -> 8 | L4: =IF(Deskriptif!K7="","",Deskriptif!K7) -> 10
A5: =Deskriptif!A8 -> P02 | B5: =Deskriptif!C8 -> 2 | C5: =Deskriptif!D8 -> 381 | D5: =IF(C5=Setup!$B$5,Setup!$C$5,Setup!$C$6) -> Robusta Temanggung (dark roast) | E5: =IF(COUNTA(Deskriptif!E8:K8)>0,1,0) -> 1 | F5: =IF(Deskriptif!E8="","",Deskriptif!E8) -> 10 | G5: =IF(Deskriptif!F8="","",Deskriptif!F8) -> 9 | H5: =IF(Deskriptif!G8="","",Deskriptif!G8) -> 11 | I5: =IF(Deskriptif!H8="","",Deskriptif!H8) -> 6 | J5: =IF(Deskriptif!I8="","",Deskriptif!I8) -> 5 | K5: =IF(Deskriptif!J8="","",Deskriptif!J8) -> 6 | L5: =IF(Deskriptif!K8="","",Deskriptif!K8) -> 8
A6: =Deskriptif!A9 -> P03 | B6: =Deskriptif!C9 -> 1 | C6: =Deskriptif!D9 -> 527 | D6: =IF(C6=Setup!$B$5,Setup!$C$5,Setup!$C$6) -> Ethiopia natural (light roast) | E6: =IF(COUNTA(Deskriptif!E9:K9)>0,1,0) -> 1 | F6: =IF(Deskriptif!E9="","",Deskriptif!E9) -> 11 | G6: =IF(Deskriptif!F9="","",Deskriptif!F9) -> 5 | H6: =IF(Deskriptif!G9="","",Deskriptif!G9) -> 9 | I6: =IF(Deskriptif!H9="","",Deskriptif!H9) -> 8 | J6: =IF(Deskriptif!I9="","",Deskriptif!I9) -> 10 | K6: =IF(Deskriptif!J9="","",Deskriptif!J9) -> 8 | L6: =IF(Deskriptif!K9="","",Deskriptif!K9) -> 6
A7: =Deskriptif!A10 -> P03 | B7: =Deskriptif!C10 -> 2 | C7: =Deskriptif!D10 -> 381 | D7: =IF(C7=Setup!$B$5,Setup!$C$5,Setup!$C$6) -> Robusta Temanggung (dark roast) | E7: =IF(COUNTA(Deskriptif!E10:K10)>0,1,0) -> 1 | F7: =IF(Deskriptif!E10="","",Deskriptif!E10) -> 8 | G7: =IF(Deskriptif!F10="","",Deskriptif!F10) -> 8 | H7: =IF(Deskriptif!G10="","",Deskriptif!G10) -> 7 | I7: =IF(Deskriptif!H10="","",Deskriptif!H10) -> 6 | J7: =IF(Deskriptif!I10="","",Deskriptif!I10) -> 4 | K7: =IF(Deskriptif!J10="","",Deskriptif!J10) -> 8 | L7: =IF(Deskriptif!K10="","",Deskriptif!K10) -> 8
A8: =Deskriptif!A11 -> P04 | B8: =Deskriptif!C11 -> 1 | C8: =Deskriptif!D11 -> 527 | D8: =IF(C8=Setup!$B$5,Setup!$C$5,Setup!$C$6) -> Ethiopia natural (light roast) | E8: =IF(COUNTA(Deskriptif!E11:K11)>0,1,0) -> 1 | F8: =IF(Deskriptif!E11="","",Deskriptif!E11) -> 8 | G8: =IF(Deskriptif!F11="","",Deskriptif!F11) -> 7 | H8: =IF(Deskriptif!G11="","",Deskriptif!G11) -> 12 | I8: =IF(Deskriptif!H11="","",Deskriptif!H11) -> 6 | J8: =IF(Deskriptif!I11="","",Deskriptif!I11) -> 12 | K8: =IF(Deskriptif!J11="","",Deskriptif!J11) -> 8 | L8: =IF(Deskriptif!K11="","",Deskriptif!K11) -> 9
A9: =Deskriptif!A12 -> P04 | B9: =Deskriptif!C12 -> 2 | C9: =Deskriptif!D12 -> 381 | D9: =IF(C9=Setup!$B$5,Setup!$C$5,Setup!$C$6) -> Robusta Temanggung (dark roast) | E9: =IF(COUNTA(Deskriptif!E12:K12)>0,1,0) -> 1 | F9: =IF(Deskriptif!E12="","",Deskriptif!E12) -> 9 | G9: =IF(Deskriptif!F12="","",Deskriptif!F12) -> 11 | H9: =IF(Deskriptif!G12="","",Deskriptif!G12) -> 8 | I9: =IF(Deskriptif!H12="","",Deskriptif!H12) -> 8 | J9: =IF(Deskriptif!I12="","",Deskriptif!I12) -> 8 | K9: =IF(Deskriptif!J12="","",Deskriptif!J12) -> 5 | L9: =IF(Deskriptif!K12="","",Deskriptif!K12) -> 10
A10: =Deskriptif!A13 -> P05 | B10: =Deskriptif!C13 -> 1 | C10: =Deskriptif!D13 -> 527 | D10: =IF(C10=Setup!$B$5,Setup!$C$5,Setup!$C$6) -> Ethiopia natural (light roast) | E10: =IF(COUNTA(Deskriptif!E13:K13)>0,1,0) -> 1 | F10: =IF(Deskriptif!E13="","",Deskriptif!E13) -> 8 | G10: =IF(Deskriptif!F13="","",Deskriptif!F13) -> 13 | H10: =IF(Deskriptif!G13="","",Deskriptif!G13) -> 8 | I10: =IF(Deskriptif!H13="","",Deskriptif!H13) -> 9 | J10: =IF(Deskriptif!I13="","",Deskriptif!I13) -> 12 | K10: =IF(Deskriptif!J13="","",Deskriptif!J13) -> 7 | L10: =IF(Deskriptif!K13="","",Deskriptif!K13) -> 5
A11: =Deskriptif!A14 -> P05 | B11: =Deskriptif!C14 -> 2 | C11: =Deskriptif!D14 -> 381 | D11: =IF(C11=Setup!$B$5,Setup!$C$5,Setup!$C$6) -> Robusta Temanggung (dark roast) | E11: =IF(COUNTA(Deskriptif!E14:K14)>0,1,0) -> 1 | F11: =IF(Deskriptif!E14="","",Deskriptif!E14) -> 8 | G11: =IF(Deskriptif!F14="","",Deskriptif!F14) -> 9 | H11: =IF(Deskriptif!G14="","",Deskriptif!G14) -> 9 | I11: =IF(Deskriptif!H14="","",Deskriptif!H14) -> 9 | J11: =IF(Deskriptif!I14="","",Deskriptif!I14) -> 5 | K11: =IF(Deskriptif!J14="","",Deskriptif!J14) -> 8 | L11: =IF(Deskriptif!K14="","",Deskriptif!K14) -> 11
A12: =Deskriptif!A15 -> P06 | B12: =Deskriptif!C15 -> 1 | C12: =Deskriptif!D15 -> 527 | D12: =IF(C12=Setup!$B$5,Setup!$C$5,Setup!$C$6) -> Ethiopia natural (light roast) | E12: =IF(COUNTA(Deskriptif!E15:K15)>0,1,0) -> 1 | F12: =IF(Deskriptif!E15="","",Deskriptif!E15) -> 11 | G12: =IF(Deskriptif!F15="","",Deskriptif!F15) -> 9 | H12: =IF(Deskriptif!G15="","",Deskriptif!G15) -> 8 | I12: =IF(Deskriptif!H15="","",Deskriptif!H15) -> 6 | J12: =IF(Deskriptif!I15="","",Deskriptif!I15) -> 11 | K12: =IF(Deskriptif!J15="","",Deskriptif!J15) -> 10 | L12: =IF(Deskriptif!K15="","",Deskriptif!K15) -> 7
A13: =Deskriptif!A16 -> P06 | B13: =Deskriptif!C16 -> 2 | C13: =Deskriptif!D16 -> 381 | D13: =IF(C13=Setup!$B$5,Setup!$C$5,Setup!$C$6) -> Robusta Temanggung (dark roast) | E13: =IF(COUNTA(Deskriptif!E16:K16)>0,1,0) -> 1 | F13: =IF(Deskriptif!E16="","",Deskriptif!E16) -> 9 | G13: =IF(Deskriptif!F16="","",Deskriptif!F16) -> 8 | H13: =IF(Deskriptif!G16="","",Deskriptif!G16) -> 7 | I13: =IF(Deskriptif!H16="","",Deskriptif!H16) -> 8 | J13: =IF(Deskriptif!I16="","",Deskriptif!I16) -> 3 | K13: =IF(Deskriptif!J16="","",Deskriptif!J16) -> 5 | L13: =IF(Deskriptif!K16="","",Deskriptif!K16) -> 10
... A61: =Deskriptif!A64 -> P30 | B61: =Deskriptif!C64 -> 2 | C61: =Deskriptif!D64 -> 381 | D61: =IF(C61=Setup!$B$5,Setup!$C$5,Setup!$C$6) -> Robusta Temanggung (dark roast) | E61: =IF(COUNTA(Deskriptif!E64:K64)>0,1,0) -> 1 | F61: =IF(Deskriptif!E64="","",Deskriptif!E64) -> 10 | G61: =IF(Deskriptif!F64="","",Deskriptif!F64) -> 11 | H61: =IF(Deskriptif!G64="","",Deskriptif!G64) -> 9 | I61: =IF(Deskriptif!H64="","",Deskriptif!H64) -> 8 | J61: =IF(Deskriptif!I64="","",Deskriptif!I64) -> 6 | K61: =IF(Deskriptif!J64="","",Deskriptif!J64) -> 3 | L61: =IF(Deskriptif!K64="","",Deskriptif!K64) -> 7

Sheet R_Afektif
A1: Panelis | B1: Urutan | C1: Sampel | D1: Kopi | E1: Terisi | F1: Fragrance | G1: Aroma | H1: Flavor | I1: Aftertaste | J1: Acidity | K1: Sweetness | L1: Mouthfeel | M1: Overall | N1: NonUniform | O1: Defective | P1: Skor_CVA
A2: =Afektif!A5 -> P01 | B2: =Afektif!C5 -> 1 | C2: =Afektif!D5 -> 527 | D2: =IF(C2=Setup!$B$5,Setup!$C$5,Setup!$C$6) -> Ethiopia natural (light roast) | E2: =IF(COUNTA(Afektif!E5:N5)>0,1,0) -> 1 | F2: =IF(Afektif!E5="","",Afektif!E5) -> 6 | G2: =IF(Afektif!F5="","",Afektif!F5) -> 7 | H2: =IF(Afektif!G5="","",Afektif!G5) -> 6 | I2: =IF(Afektif!H5="","",Afektif!H5) -> 8 | J2: =IF(Afektif!I5="","",Afektif!I5) -> 8 | K2: =IF(Afektif!J5="","",Afektif!J5) -> 7 | L2: =IF(Afektif!K5="","",Afektif!K5) -> 8 | M2: =IF(Afektif!L5="","",Afektif!L5) -> 9 | ... P2: =IF(Afektif!O5="","",Afektif!O5) -> 91.46875
A3: =Afektif!A6 -> P01 | B3: =Afektif!C6 -> 2 | C3: =Afektif!D6 -> 381 | D3: =IF(C3=Setup!$B$5,Setup!$C$5,Setup!$C$6) -> Robusta Temanggung (dark roast) | E3: =IF(COUNTA(Afektif!E6:N6)>0,1,0) -> 1 | F3: =IF(Afektif!E6="","",Afektif!E6) -> 7 | G3: =IF(Afektif!F6="","",Afektif!F6) -> 6 | H3: =IF(Afektif!G6="","",Afektif!G6) -> 6 | I3: =IF(Afektif!H6="","",Afektif!H6) -> 7 | J3: =IF(Afektif!I6="","",Afektif!I6) -> 6 | K3: =IF(Afektif!J6="","",Afektif!J6) -> 6 | L3: =IF(Afektif!K6="","",Afektif!K6) -> 6 | M3: =IF(Afektif!L6="","",Afektif!L6) -> 4 | ... P3: =IF(Afektif!O6="","",Afektif!O6) -> 84.25
A4: =Afektif!A7 -> P02 | B4: =Afektif!C7 -> 1 | C4: =Afektif!D7 -> 527 | D4: =IF(C4=Setup!$B$5,Setup!$C$5,Setup!$C$6) -> Ethiopia natural (light roast) | E4: =IF(COUNTA(Afektif!E7:N7)>0,1,0) -> 1 | F4: =IF(Afektif!E7="","",Afektif!E7) -> 8 | G4: =IF(Afektif!F7="","",Afektif!F7) -> 8 | H4: =IF(Afektif!G7="","",Afektif!G7) -> 7 | I4: =IF(Afektif!H7="","",Afektif!H7) -> 7 | J4: =IF(Afektif!I7="","",Afektif!I7) -> 9 | K4: =IF(Afektif!J7="","",Afektif!J7) -> 8 | L4: =IF(Afektif!K7="","",Afektif!K7) -> 7 | M4: =IF(Afektif!L7="","",Afektif!L7) -> 9 | ... P4: =IF(Afektif!O7="","",Afektif!O7) -> 92.09375
